2019-03-04 15:21:04,429 -  nornir.core -     INFO -        run() - Running task 'netmiko_send_command' with num_workers: 100
2019-03-04 15:21:04,429 -  nornir.core -     INFO -        run() - Running task 'netmiko_send_command' with num_workers: 100
2019-03-04 15:21:04,432 -  nornir.core -    DEBUG -        run() - {'command_string': 'sh int status'}
2019-03-04 15:21:04,432 -  nornir.core -    DEBUG -        run() - {'command_string': 'sh int status'}
2019-03-04 15:21:04,475 - nornir.core.task -     INFO -      start() - MBuck-Test: netmiko_send_command: running task
2019-03-04 15:21:04,475 - nornir.core.task -     INFO -      start() - MBuck-Test: netmiko_send_command: running task
2019-03-04 15:21:04,478 - nornir.core.task -    ERROR -      start() - MBuck-Test: Traceback (most recent call last):
  File "C:\Users\m_buck\AppData\Local\Programs\Python\Python37-32\lib\site-packages\nornir\core\task.py", line 62, in start
    r = self.task(self, **self.params)
  File "C:\Users\m_buck\AppData\Local\Programs\Python\Python37-32\lib\site-packages\nornir\plugins\tasks\networking\netmiko_send_command.py", line 26, in netmiko_send_command
    net_connect = task.host.get_connection("netmiko", task.nornir.config)
  File "C:\Users\m_buck\AppData\Local\Programs\Python\Python37-32\lib\site-packages\nornir\core\inventory.py", line 297, in get_connection
    **self.get_connection_parameters(connection).dict(),
  File "C:\Users\m_buck\AppData\Local\Programs\Python\Python37-32\lib\site-packages\nornir\core\inventory.py", line 347, in open_connection
    configuration=configuration,
  File "C:\Users\m_buck\AppData\Local\Programs\Python\Python37-32\lib\site-packages\nornir\plugins\connections\netmiko.py", line 51, in open
    self.connection = ConnectHandler(**parameters)
  File "C:\Users\m_buck\AppData\Local\Programs\Python\Python37-32\lib\site-packages\netmiko\ssh_dispatcher.py", line 214, in ConnectHandler
    if kwargs['device_type'] not in platforms:
KeyError: 'device_type'

2019-03-04 15:21:04,478 - nornir.core.task -    ERROR -      start() - MBuck-Test: Traceback (most recent call last):
  File "C:\Users\m_buck\AppData\Local\Programs\Python\Python37-32\lib\site-packages\nornir\core\task.py", line 62, in start
    r = self.task(self, **self.params)
  File "C:\Users\m_buck\AppData\Local\Programs\Python\Python37-32\lib\site-packages\nornir\plugins\tasks\networking\netmiko_send_command.py", line 26, in netmiko_send_command
    net_connect = task.host.get_connection("netmiko", task.nornir.config)
  File "C:\Users\m_buck\AppData\Local\Programs\Python\Python37-32\lib\site-packages\nornir\core\inventory.py", line 297, in get_connection
    **self.get_connection_parameters(connection).dict(),
  File "C:\Users\m_buck\AppData\Local\Programs\Python\Python37-32\lib\site-packages\nornir\core\inventory.py", line 347, in open_connection
    configuration=configuration,
  File "C:\Users\m_buck\AppData\Local\Programs\Python\Python37-32\lib\site-packages\nornir\plugins\connections\netmiko.py", line 51, in open
    self.connection = ConnectHandler(**parameters)
  File "C:\Users\m_buck\AppData\Local\Programs\Python\Python37-32\lib\site-packages\netmiko\ssh_dispatcher.py", line 214, in ConnectHandler
    if kwargs['device_type'] not in platforms:
KeyError: 'device_type'

2019-03-04 15:37:08,592 -  nornir.core -     INFO -        run() - Running task 'netmiko_send_command' with num_workers: 100
2019-03-04 15:37:08,592 -  nornir.core -     INFO -        run() - Running task 'netmiko_send_command' with num_workers: 100
2019-03-04 15:37:08,592 -  nornir.core -    DEBUG -        run() - {'command_string': 'sh int status'}
2019-03-04 15:37:08,592 -  nornir.core -    DEBUG -        run() - {'command_string': 'sh int status'}
2019-03-04 15:37:08,629 - nornir.core.task -     INFO -      start() - MBuck-Test: netmiko_send_command: running task
2019-03-04 15:37:08,629 - nornir.core.task -     INFO -      start() - MBuck-Test: netmiko_send_command: running task
2019-03-04 15:37:08,635 - nornir.core.task -    ERROR -      start() - MBuck-Test: Traceback (most recent call last):
  File "C:\Users\m_buck\AppData\Local\Programs\Python\Python37-32\lib\site-packages\nornir\core\task.py", line 62, in start
    r = self.task(self, **self.params)
  File "C:\Users\m_buck\AppData\Local\Programs\Python\Python37-32\lib\site-packages\nornir\plugins\tasks\networking\netmiko_send_command.py", line 26, in netmiko_send_command
    net_connect = task.host.get_connection("netmiko", task.nornir.config)
  File "C:\Users\m_buck\AppData\Local\Programs\Python\Python37-32\lib\site-packages\nornir\core\inventory.py", line 297, in get_connection
    **self.get_connection_parameters(connection).dict(),
  File "C:\Users\m_buck\AppData\Local\Programs\Python\Python37-32\lib\site-packages\nornir\core\inventory.py", line 347, in open_connection
    configuration=configuration,
  File "C:\Users\m_buck\AppData\Local\Programs\Python\Python37-32\lib\site-packages\nornir\plugins\connections\netmiko.py", line 51, in open
    self.connection = ConnectHandler(**parameters)
  File "C:\Users\m_buck\AppData\Local\Programs\Python\Python37-32\lib\site-packages\netmiko\ssh_dispatcher.py", line 214, in ConnectHandler
    if kwargs['device_type'] not in platforms:
KeyError: 'device_type'

2019-03-04 15:37:08,635 - nornir.core.task -    ERROR -      start() - MBuck-Test: Traceback (most recent call last):
  File "C:\Users\m_buck\AppData\Local\Programs\Python\Python37-32\lib\site-packages\nornir\core\task.py", line 62, in start
    r = self.task(self, **self.params)
  File "C:\Users\m_buck\AppData\Local\Programs\Python\Python37-32\lib\site-packages\nornir\plugins\tasks\networking\netmiko_send_command.py", line 26, in netmiko_send_command
    net_connect = task.host.get_connection("netmiko", task.nornir.config)
  File "C:\Users\m_buck\AppData\Local\Programs\Python\Python37-32\lib\site-packages\nornir\core\inventory.py", line 297, in get_connection
    **self.get_connection_parameters(connection).dict(),
  File "C:\Users\m_buck\AppData\Local\Programs\Python\Python37-32\lib\site-packages\nornir\core\inventory.py", line 347, in open_connection
    configuration=configuration,
  File "C:\Users\m_buck\AppData\Local\Programs\Python\Python37-32\lib\site-packages\nornir\plugins\connections\netmiko.py", line 51, in open
    self.connection = ConnectHandler(**parameters)
  File "C:\Users\m_buck\AppData\Local\Programs\Python\Python37-32\lib\site-packages\netmiko\ssh_dispatcher.py", line 214, in ConnectHandler
    if kwargs['device_type'] not in platforms:
KeyError: 'device_type'

2019-03-04 15:45:53,948 -  nornir.core -     INFO -        run() - Running task 'netmiko_send_command' with num_workers: 100
2019-03-04 15:45:53,948 -  nornir.core -     INFO -        run() - Running task 'netmiko_send_command' with num_workers: 100
2019-03-04 15:45:53,948 -  nornir.core -    DEBUG -        run() - {'command_string': 'sh int status'}
2019-03-04 15:45:53,948 -  nornir.core -    DEBUG -        run() - {'command_string': 'sh int status'}
2019-03-04 15:45:53,990 - nornir.core.task -     INFO -      start() - MBuck-Test: netmiko_send_command: running task
2019-03-04 15:45:53,990 - nornir.core.task -     INFO -      start() - MBuck-Test: netmiko_send_command: running task
2019-03-04 15:45:53,993 - nornir.core.task -    ERROR -      start() - MBuck-Test: Traceback (most recent call last):
  File "C:\Users\m_buck\AppData\Local\Programs\Python\Python37-32\lib\site-packages\nornir\core\task.py", line 62, in start
    r = self.task(self, **self.params)
  File "C:\Users\m_buck\AppData\Local\Programs\Python\Python37-32\lib\site-packages\nornir\plugins\tasks\networking\netmiko_send_command.py", line 26, in netmiko_send_command
    net_connect = task.host.get_connection("netmiko", task.nornir.config)
  File "C:\Users\m_buck\AppData\Local\Programs\Python\Python37-32\lib\site-packages\nornir\core\inventory.py", line 297, in get_connection
    **self.get_connection_parameters(connection).dict(),
  File "C:\Users\m_buck\AppData\Local\Programs\Python\Python37-32\lib\site-packages\nornir\core\inventory.py", line 347, in open_connection
    configuration=configuration,
  File "C:\Users\m_buck\AppData\Local\Programs\Python\Python37-32\lib\site-packages\nornir\plugins\connections\netmiko.py", line 51, in open
    self.connection = ConnectHandler(**parameters)
  File "C:\Users\m_buck\AppData\Local\Programs\Python\Python37-32\lib\site-packages\netmiko\ssh_dispatcher.py", line 214, in ConnectHandler
    if kwargs['device_type'] not in platforms:
KeyError: 'device_type'

2019-03-04 15:45:53,993 - nornir.core.task -    ERROR -      start() - MBuck-Test: Traceback (most recent call last):
  File "C:\Users\m_buck\AppData\Local\Programs\Python\Python37-32\lib\site-packages\nornir\core\task.py", line 62, in start
    r = self.task(self, **self.params)
  File "C:\Users\m_buck\AppData\Local\Programs\Python\Python37-32\lib\site-packages\nornir\plugins\tasks\networking\netmiko_send_command.py", line 26, in netmiko_send_command
    net_connect = task.host.get_connection("netmiko", task.nornir.config)
  File "C:\Users\m_buck\AppData\Local\Programs\Python\Python37-32\lib\site-packages\nornir\core\inventory.py", line 297, in get_connection
    **self.get_connection_parameters(connection).dict(),
  File "C:\Users\m_buck\AppData\Local\Programs\Python\Python37-32\lib\site-packages\nornir\core\inventory.py", line 347, in open_connection
    configuration=configuration,
  File "C:\Users\m_buck\AppData\Local\Programs\Python\Python37-32\lib\site-packages\nornir\plugins\connections\netmiko.py", line 51, in open
    self.connection = ConnectHandler(**parameters)
  File "C:\Users\m_buck\AppData\Local\Programs\Python\Python37-32\lib\site-packages\netmiko\ssh_dispatcher.py", line 214, in ConnectHandler
    if kwargs['device_type'] not in platforms:
KeyError: 'device_type'

2019-03-04 16:01:01,773 -  nornir.core -     INFO -        run() - Running task 'netmiko_send_command' with num_workers: 100
2019-03-04 16:01:01,773 -  nornir.core -     INFO -        run() - Running task 'netmiko_send_command' with num_workers: 100
2019-03-04 16:01:01,773 -  nornir.core -    DEBUG -        run() - {'command_string': 'sh int status'}
2019-03-04 16:01:01,773 -  nornir.core -    DEBUG -        run() - {'command_string': 'sh int status'}
2019-03-04 16:01:01,806 - nornir.core.task -     INFO -      start() - MBuck-Test: netmiko_send_command: running task
2019-03-04 16:01:01,806 - nornir.core.task -     INFO -      start() - MBuck-Test: netmiko_send_command: running task
2019-03-04 16:01:01,809 - nornir.core.task -    ERROR -      start() - MBuck-Test: Traceback (most recent call last):
  File "C:\Users\m_buck\AppData\Local\Programs\Python\Python37-32\lib\site-packages\nornir\core\task.py", line 62, in start
    r = self.task(self, **self.params)
  File "C:\Users\m_buck\AppData\Local\Programs\Python\Python37-32\lib\site-packages\nornir\plugins\tasks\networking\netmiko_send_command.py", line 26, in netmiko_send_command
    net_connect = task.host.get_connection("netmiko", task.nornir.config)
  File "C:\Users\m_buck\AppData\Local\Programs\Python\Python37-32\lib\site-packages\nornir\core\inventory.py", line 297, in get_connection
    **self.get_connection_parameters(connection).dict(),
  File "C:\Users\m_buck\AppData\Local\Programs\Python\Python37-32\lib\site-packages\nornir\core\inventory.py", line 347, in open_connection
    configuration=configuration,
  File "C:\Users\m_buck\AppData\Local\Programs\Python\Python37-32\lib\site-packages\nornir\plugins\connections\netmiko.py", line 51, in open
    self.connection = ConnectHandler(**parameters)
  File "C:\Users\m_buck\AppData\Local\Programs\Python\Python37-32\lib\site-packages\netmiko\ssh_dispatcher.py", line 214, in ConnectHandler
    if kwargs['device_type'] not in platforms:
KeyError: 'device_type'

2019-03-04 16:01:01,809 - nornir.core.task -    ERROR -      start() - MBuck-Test: Traceback (most recent call last):
  File "C:\Users\m_buck\AppData\Local\Programs\Python\Python37-32\lib\site-packages\nornir\core\task.py", line 62, in start
    r = self.task(self, **self.params)
  File "C:\Users\m_buck\AppData\Local\Programs\Python\Python37-32\lib\site-packages\nornir\plugins\tasks\networking\netmiko_send_command.py", line 26, in netmiko_send_command
    net_connect = task.host.get_connection("netmiko", task.nornir.config)
  File "C:\Users\m_buck\AppData\Local\Programs\Python\Python37-32\lib\site-packages\nornir\core\inventory.py", line 297, in get_connection
    **self.get_connection_parameters(connection).dict(),
  File "C:\Users\m_buck\AppData\Local\Programs\Python\Python37-32\lib\site-packages\nornir\core\inventory.py", line 347, in open_connection
    configuration=configuration,
  File "C:\Users\m_buck\AppData\Local\Programs\Python\Python37-32\lib\site-packages\nornir\plugins\connections\netmiko.py", line 51, in open
    self.connection = ConnectHandler(**parameters)
  File "C:\Users\m_buck\AppData\Local\Programs\Python\Python37-32\lib\site-packages\netmiko\ssh_dispatcher.py", line 214, in ConnectHandler
    if kwargs['device_type'] not in platforms:
KeyError: 'device_type'

2019-03-04 16:03:31,457 -  nornir.core -     INFO -        run() - Running task 'netmiko_send_command' with num_workers: 100
2019-03-04 16:03:31,457 -  nornir.core -     INFO -        run() - Running task 'netmiko_send_command' with num_workers: 100
2019-03-04 16:03:31,457 -  nornir.core -    DEBUG -        run() - {'command_string': 'sh int status'}
2019-03-04 16:03:31,457 -  nornir.core -    DEBUG -        run() - {'command_string': 'sh int status'}
2019-03-04 16:03:31,494 - nornir.core.task -     INFO -      start() - MBuck-Test: netmiko_send_command: running task
2019-03-04 16:03:31,494 - nornir.core.task -     INFO -      start() - MBuck-Test: netmiko_send_command: running task
2019-03-04 16:03:31,498 - nornir.core.task -    ERROR -      start() - MBuck-Test: Traceback (most recent call last):
  File "C:\Users\m_buck\AppData\Local\Programs\Python\Python37-32\lib\site-packages\nornir\core\task.py", line 62, in start
    r = self.task(self, **self.params)
  File "C:\Users\m_buck\AppData\Local\Programs\Python\Python37-32\lib\site-packages\nornir\plugins\tasks\networking\netmiko_send_command.py", line 26, in netmiko_send_command
    net_connect = task.host.get_connection("netmiko", task.nornir.config)
  File "C:\Users\m_buck\AppData\Local\Programs\Python\Python37-32\lib\site-packages\nornir\core\inventory.py", line 297, in get_connection
    **self.get_connection_parameters(connection).dict(),
  File "C:\Users\m_buck\AppData\Local\Programs\Python\Python37-32\lib\site-packages\nornir\core\inventory.py", line 347, in open_connection
    configuration=configuration,
  File "C:\Users\m_buck\AppData\Local\Programs\Python\Python37-32\lib\site-packages\nornir\plugins\connections\netmiko.py", line 51, in open
    self.connection = ConnectHandler(**parameters)
  File "C:\Users\m_buck\AppData\Local\Programs\Python\Python37-32\lib\site-packages\netmiko\ssh_dispatcher.py", line 214, in ConnectHandler
    if kwargs['device_type'] not in platforms:
KeyError: 'device_type'

2019-03-04 16:03:31,498 - nornir.core.task -    ERROR -      start() - MBuck-Test: Traceback (most recent call last):
  File "C:\Users\m_buck\AppData\Local\Programs\Python\Python37-32\lib\site-packages\nornir\core\task.py", line 62, in start
    r = self.task(self, **self.params)
  File "C:\Users\m_buck\AppData\Local\Programs\Python\Python37-32\lib\site-packages\nornir\plugins\tasks\networking\netmiko_send_command.py", line 26, in netmiko_send_command
    net_connect = task.host.get_connection("netmiko", task.nornir.config)
  File "C:\Users\m_buck\AppData\Local\Programs\Python\Python37-32\lib\site-packages\nornir\core\inventory.py", line 297, in get_connection
    **self.get_connection_parameters(connection).dict(),
  File "C:\Users\m_buck\AppData\Local\Programs\Python\Python37-32\lib\site-packages\nornir\core\inventory.py", line 347, in open_connection
    configuration=configuration,
  File "C:\Users\m_buck\AppData\Local\Programs\Python\Python37-32\lib\site-packages\nornir\plugins\connections\netmiko.py", line 51, in open
    self.connection = ConnectHandler(**parameters)
  File "C:\Users\m_buck\AppData\Local\Programs\Python\Python37-32\lib\site-packages\netmiko\ssh_dispatcher.py", line 214, in ConnectHandler
    if kwargs['device_type'] not in platforms:
KeyError: 'device_type'

2019-03-04 16:06:54,238 -  nornir.core -     INFO -        run() - Running task 'netmiko_send_command' with num_workers: 100
2019-03-04 16:06:54,238 -  nornir.core -     INFO -        run() - Running task 'netmiko_send_command' with num_workers: 100
2019-03-04 16:06:54,239 -  nornir.core -    DEBUG -        run() - {'command_string': 'sh int status'}
2019-03-04 16:06:54,239 -  nornir.core -    DEBUG -        run() - {'command_string': 'sh int status'}
2019-03-04 16:06:54,273 - nornir.core.task -     INFO -      start() - MBuck-Test: netmiko_send_command: running task
2019-03-04 16:06:54,273 - nornir.core.task -     INFO -      start() - MBuck-Test: netmiko_send_command: running task
2019-03-04 16:06:54,275 - nornir.core.task -    ERROR -      start() - MBuck-Test: Traceback (most recent call last):
  File "C:\Users\m_buck\AppData\Local\Programs\Python\Python37-32\lib\site-packages\nornir\core\task.py", line 62, in start
    r = self.task(self, **self.params)
  File "C:\Users\m_buck\AppData\Local\Programs\Python\Python37-32\lib\site-packages\nornir\plugins\tasks\networking\netmiko_send_command.py", line 26, in netmiko_send_command
    net_connect = task.host.get_connection("netmiko", task.nornir.config)
  File "C:\Users\m_buck\AppData\Local\Programs\Python\Python37-32\lib\site-packages\nornir\core\inventory.py", line 297, in get_connection
    **self.get_connection_parameters(connection).dict(),
  File "C:\Users\m_buck\AppData\Local\Programs\Python\Python37-32\lib\site-packages\nornir\core\inventory.py", line 347, in open_connection
    configuration=configuration,
  File "C:\Users\m_buck\AppData\Local\Programs\Python\Python37-32\lib\site-packages\nornir\plugins\connections\netmiko.py", line 51, in open
    self.connection = ConnectHandler(**parameters)
  File "C:\Users\m_buck\AppData\Local\Programs\Python\Python37-32\lib\site-packages\netmiko\ssh_dispatcher.py", line 214, in ConnectHandler
    if kwargs['device_type'] not in platforms:
KeyError: 'device_type'

2019-03-04 16:06:54,275 - nornir.core.task -    ERROR -      start() - MBuck-Test: Traceback (most recent call last):
  File "C:\Users\m_buck\AppData\Local\Programs\Python\Python37-32\lib\site-packages\nornir\core\task.py", line 62, in start
    r = self.task(self, **self.params)
  File "C:\Users\m_buck\AppData\Local\Programs\Python\Python37-32\lib\site-packages\nornir\plugins\tasks\networking\netmiko_send_command.py", line 26, in netmiko_send_command
    net_connect = task.host.get_connection("netmiko", task.nornir.config)
  File "C:\Users\m_buck\AppData\Local\Programs\Python\Python37-32\lib\site-packages\nornir\core\inventory.py", line 297, in get_connection
    **self.get_connection_parameters(connection).dict(),
  File "C:\Users\m_buck\AppData\Local\Programs\Python\Python37-32\lib\site-packages\nornir\core\inventory.py", line 347, in open_connection
    configuration=configuration,
  File "C:\Users\m_buck\AppData\Local\Programs\Python\Python37-32\lib\site-packages\nornir\plugins\connections\netmiko.py", line 51, in open
    self.connection = ConnectHandler(**parameters)
  File "C:\Users\m_buck\AppData\Local\Programs\Python\Python37-32\lib\site-packages\netmiko\ssh_dispatcher.py", line 214, in ConnectHandler
    if kwargs['device_type'] not in platforms:
KeyError: 'device_type'

2019-03-04 16:28:50,777 -  nornir.core -     INFO -        run() - Running task 'netmiko_send_command' with num_workers: 100
2019-03-04 16:28:50,777 -  nornir.core -     INFO -        run() - Running task 'netmiko_send_command' with num_workers: 100
2019-03-04 16:28:50,777 -  nornir.core -    DEBUG -        run() - {'command_string': 'sh int status'}
2019-03-04 16:28:50,777 -  nornir.core -    DEBUG -        run() - {'command_string': 'sh int status'}
2019-03-04 16:28:50,821 - nornir.core.task -     INFO -      start() - MBuck-Test: netmiko_send_command: running task
2019-03-04 16:28:50,821 - nornir.core.task -     INFO -      start() - MBuck-Test: netmiko_send_command: running task
2019-03-04 16:28:50,824 - nornir.core.task -    ERROR -      start() - MBuck-Test: Traceback (most recent call last):
  File "C:\Users\m_buck\AppData\Local\Programs\Python\Python37-32\lib\site-packages\nornir\core\task.py", line 62, in start
    r = self.task(self, **self.params)
  File "C:\Users\m_buck\AppData\Local\Programs\Python\Python37-32\lib\site-packages\nornir\plugins\tasks\networking\netmiko_send_command.py", line 26, in netmiko_send_command
    net_connect = task.host.get_connection("netmiko", task.nornir.config)
  File "C:\Users\m_buck\AppData\Local\Programs\Python\Python37-32\lib\site-packages\nornir\core\inventory.py", line 297, in get_connection
    **self.get_connection_parameters(connection).dict(),
  File "C:\Users\m_buck\AppData\Local\Programs\Python\Python37-32\lib\site-packages\nornir\core\inventory.py", line 347, in open_connection
    configuration=configuration,
  File "C:\Users\m_buck\AppData\Local\Programs\Python\Python37-32\lib\site-packages\nornir\plugins\connections\netmiko.py", line 51, in open
    self.connection = ConnectHandler(**parameters)
  File "C:\Users\m_buck\AppData\Local\Programs\Python\Python37-32\lib\site-packages\netmiko\ssh_dispatcher.py", line 214, in ConnectHandler
    if kwargs['device_type'] not in platforms:
KeyError: 'device_type'

2019-03-04 16:28:50,824 - nornir.core.task -    ERROR -      start() - MBuck-Test: Traceback (most recent call last):
  File "C:\Users\m_buck\AppData\Local\Programs\Python\Python37-32\lib\site-packages\nornir\core\task.py", line 62, in start
    r = self.task(self, **self.params)
  File "C:\Users\m_buck\AppData\Local\Programs\Python\Python37-32\lib\site-packages\nornir\plugins\tasks\networking\netmiko_send_command.py", line 26, in netmiko_send_command
    net_connect = task.host.get_connection("netmiko", task.nornir.config)
  File "C:\Users\m_buck\AppData\Local\Programs\Python\Python37-32\lib\site-packages\nornir\core\inventory.py", line 297, in get_connection
    **self.get_connection_parameters(connection).dict(),
  File "C:\Users\m_buck\AppData\Local\Programs\Python\Python37-32\lib\site-packages\nornir\core\inventory.py", line 347, in open_connection
    configuration=configuration,
  File "C:\Users\m_buck\AppData\Local\Programs\Python\Python37-32\lib\site-packages\nornir\plugins\connections\netmiko.py", line 51, in open
    self.connection = ConnectHandler(**parameters)
  File "C:\Users\m_buck\AppData\Local\Programs\Python\Python37-32\lib\site-packages\netmiko\ssh_dispatcher.py", line 214, in ConnectHandler
    if kwargs['device_type'] not in platforms:
KeyError: 'device_type'

2019-03-05 12:31:27,103 -  nornir.core -     INFO -        run() - Running task 'netmiko_send_command' with num_workers: 100
2019-03-05 12:31:27,103 -  nornir.core -     INFO -        run() - Running task 'netmiko_send_command' with num_workers: 100
2019-03-05 12:31:27,104 -  nornir.core -    DEBUG -        run() - {'command_string': 'sh int status'}
2019-03-05 12:31:27,104 -  nornir.core -    DEBUG -        run() - {'command_string': 'sh int status'}
2019-03-05 12:31:27,145 - nornir.core.task -     INFO -      start() - GNS.CE1: netmiko_send_command: running task
2019-03-05 12:31:27,145 - nornir.core.task -     INFO -      start() - GNS.CE2: netmiko_send_command: running task
2019-03-05 12:31:27,145 - nornir.core.task -     INFO -      start() - GNS.CE2: netmiko_send_command: running task
2019-03-05 12:31:27,145 - nornir.core.task -     INFO -      start() - GNS.CE3: netmiko_send_command: running task
2019-03-05 12:31:27,145 - nornir.core.task -     INFO -      start() - GNS.CE1: netmiko_send_command: running task
2019-03-05 12:31:27,145 - nornir.core.task -     INFO -      start() - GNS.CE3: netmiko_send_command: running task
2019-03-05 12:31:27,159 - nornir.core.task -    ERROR -      start() - GNS.CE2: Traceback (most recent call last):
  File "C:\Users\m_buck\AppData\Local\Programs\Python\Python37-32\lib\site-packages\nornir\core\task.py", line 62, in start
    r = self.task(self, **self.params)
  File "C:\Users\m_buck\AppData\Local\Programs\Python\Python37-32\lib\site-packages\nornir\plugins\tasks\networking\netmiko_send_command.py", line 26, in netmiko_send_command
    net_connect = task.host.get_connection("netmiko", task.nornir.config)
  File "C:\Users\m_buck\AppData\Local\Programs\Python\Python37-32\lib\site-packages\nornir\core\inventory.py", line 297, in get_connection
    **self.get_connection_parameters(connection).dict(),
  File "C:\Users\m_buck\AppData\Local\Programs\Python\Python37-32\lib\site-packages\nornir\core\inventory.py", line 347, in open_connection
    configuration=configuration,
  File "C:\Users\m_buck\AppData\Local\Programs\Python\Python37-32\lib\site-packages\nornir\plugins\connections\netmiko.py", line 51, in open
    self.connection = ConnectHandler(**parameters)
  File "C:\Users\m_buck\AppData\Local\Programs\Python\Python37-32\lib\site-packages\netmiko\ssh_dispatcher.py", line 214, in ConnectHandler
    if kwargs['device_type'] not in platforms:
KeyError: 'device_type'

2019-03-05 12:31:27,159 - nornir.core.task -    ERROR -      start() - GNS.CE2: Traceback (most recent call last):
  File "C:\Users\m_buck\AppData\Local\Programs\Python\Python37-32\lib\site-packages\nornir\core\task.py", line 62, in start
    r = self.task(self, **self.params)
  File "C:\Users\m_buck\AppData\Local\Programs\Python\Python37-32\lib\site-packages\nornir\plugins\tasks\networking\netmiko_send_command.py", line 26, in netmiko_send_command
    net_connect = task.host.get_connection("netmiko", task.nornir.config)
  File "C:\Users\m_buck\AppData\Local\Programs\Python\Python37-32\lib\site-packages\nornir\core\inventory.py", line 297, in get_connection
    **self.get_connection_parameters(connection).dict(),
  File "C:\Users\m_buck\AppData\Local\Programs\Python\Python37-32\lib\site-packages\nornir\core\inventory.py", line 347, in open_connection
    configuration=configuration,
  File "C:\Users\m_buck\AppData\Local\Programs\Python\Python37-32\lib\site-packages\nornir\plugins\connections\netmiko.py", line 51, in open
    self.connection = ConnectHandler(**parameters)
  File "C:\Users\m_buck\AppData\Local\Programs\Python\Python37-32\lib\site-packages\netmiko\ssh_dispatcher.py", line 214, in ConnectHandler
    if kwargs['device_type'] not in platforms:
KeyError: 'device_type'

2019-03-05 12:31:27,159 - nornir.core.task -    ERROR -      start() - GNS.CE1: Traceback (most recent call last):
  File "C:\Users\m_buck\AppData\Local\Programs\Python\Python37-32\lib\site-packages\nornir\core\task.py", line 62, in start
    r = self.task(self, **self.params)
  File "C:\Users\m_buck\AppData\Local\Programs\Python\Python37-32\lib\site-packages\nornir\plugins\tasks\networking\netmiko_send_command.py", line 26, in netmiko_send_command
    net_connect = task.host.get_connection("netmiko", task.nornir.config)
  File "C:\Users\m_buck\AppData\Local\Programs\Python\Python37-32\lib\site-packages\nornir\core\inventory.py", line 297, in get_connection
    **self.get_connection_parameters(connection).dict(),
  File "C:\Users\m_buck\AppData\Local\Programs\Python\Python37-32\lib\site-packages\nornir\core\inventory.py", line 347, in open_connection
    configuration=configuration,
  File "C:\Users\m_buck\AppData\Local\Programs\Python\Python37-32\lib\site-packages\nornir\plugins\connections\netmiko.py", line 51, in open
    self.connection = ConnectHandler(**parameters)
  File "C:\Users\m_buck\AppData\Local\Programs\Python\Python37-32\lib\site-packages\netmiko\ssh_dispatcher.py", line 214, in ConnectHandler
    if kwargs['device_type'] not in platforms:
KeyError: 'device_type'

2019-03-05 12:31:27,159 - nornir.core.task -    ERROR -      start() - GNS.CE1: Traceback (most recent call last):
  File "C:\Users\m_buck\AppData\Local\Programs\Python\Python37-32\lib\site-packages\nornir\core\task.py", line 62, in start
    r = self.task(self, **self.params)
  File "C:\Users\m_buck\AppData\Local\Programs\Python\Python37-32\lib\site-packages\nornir\plugins\tasks\networking\netmiko_send_command.py", line 26, in netmiko_send_command
    net_connect = task.host.get_connection("netmiko", task.nornir.config)
  File "C:\Users\m_buck\AppData\Local\Programs\Python\Python37-32\lib\site-packages\nornir\core\inventory.py", line 297, in get_connection
    **self.get_connection_parameters(connection).dict(),
  File "C:\Users\m_buck\AppData\Local\Programs\Python\Python37-32\lib\site-packages\nornir\core\inventory.py", line 347, in open_connection
    configuration=configuration,
  File "C:\Users\m_buck\AppData\Local\Programs\Python\Python37-32\lib\site-packages\nornir\plugins\connections\netmiko.py", line 51, in open
    self.connection = ConnectHandler(**parameters)
  File "C:\Users\m_buck\AppData\Local\Programs\Python\Python37-32\lib\site-packages\netmiko\ssh_dispatcher.py", line 214, in ConnectHandler
    if kwargs['device_type'] not in platforms:
KeyError: 'device_type'

2019-03-05 12:31:27,161 - nornir.core.task -    ERROR -      start() - GNS.CE3: Traceback (most recent call last):
  File "C:\Users\m_buck\AppData\Local\Programs\Python\Python37-32\lib\site-packages\nornir\core\task.py", line 62, in start
    r = self.task(self, **self.params)
  File "C:\Users\m_buck\AppData\Local\Programs\Python\Python37-32\lib\site-packages\nornir\plugins\tasks\networking\netmiko_send_command.py", line 26, in netmiko_send_command
    net_connect = task.host.get_connection("netmiko", task.nornir.config)
  File "C:\Users\m_buck\AppData\Local\Programs\Python\Python37-32\lib\site-packages\nornir\core\inventory.py", line 297, in get_connection
    **self.get_connection_parameters(connection).dict(),
  File "C:\Users\m_buck\AppData\Local\Programs\Python\Python37-32\lib\site-packages\nornir\core\inventory.py", line 347, in open_connection
    configuration=configuration,
  File "C:\Users\m_buck\AppData\Local\Programs\Python\Python37-32\lib\site-packages\nornir\plugins\connections\netmiko.py", line 51, in open
    self.connection = ConnectHandler(**parameters)
  File "C:\Users\m_buck\AppData\Local\Programs\Python\Python37-32\lib\site-packages\netmiko\ssh_dispatcher.py", line 214, in ConnectHandler
    if kwargs['device_type'] not in platforms:
KeyError: 'device_type'

2019-03-05 12:31:27,161 - nornir.core.task -    ERROR -      start() - GNS.CE3: Traceback (most recent call last):
  File "C:\Users\m_buck\AppData\Local\Programs\Python\Python37-32\lib\site-packages\nornir\core\task.py", line 62, in start
    r = self.task(self, **self.params)
  File "C:\Users\m_buck\AppData\Local\Programs\Python\Python37-32\lib\site-packages\nornir\plugins\tasks\networking\netmiko_send_command.py", line 26, in netmiko_send_command
    net_connect = task.host.get_connection("netmiko", task.nornir.config)
  File "C:\Users\m_buck\AppData\Local\Programs\Python\Python37-32\lib\site-packages\nornir\core\inventory.py", line 297, in get_connection
    **self.get_connection_parameters(connection).dict(),
  File "C:\Users\m_buck\AppData\Local\Programs\Python\Python37-32\lib\site-packages\nornir\core\inventory.py", line 347, in open_connection
    configuration=configuration,
  File "C:\Users\m_buck\AppData\Local\Programs\Python\Python37-32\lib\site-packages\nornir\plugins\connections\netmiko.py", line 51, in open
    self.connection = ConnectHandler(**parameters)
  File "C:\Users\m_buck\AppData\Local\Programs\Python\Python37-32\lib\site-packages\netmiko\ssh_dispatcher.py", line 214, in ConnectHandler
    if kwargs['device_type'] not in platforms:
KeyError: 'device_type'

2019-03-05 12:31:27,250 -  nornir.core -     INFO -        run() - Running task 'netmiko_send_command' with num_workers: 100
2019-03-05 12:31:27,250 -  nornir.core -     INFO -        run() - Running task 'netmiko_send_command' with num_workers: 100
2019-03-05 12:31:27,251 -  nornir.core -    DEBUG -        run() - {'command_string': 'sh log'}
2019-03-05 12:31:27,251 -  nornir.core -    DEBUG -        run() - {'command_string': 'sh log'}
2019-03-05 12:31:27,377 -  nornir.core -     INFO -        run() - Running task 'netmiko_send_command' with num_workers: 100
2019-03-05 12:31:27,377 -  nornir.core -     INFO -        run() - Running task 'netmiko_send_command' with num_workers: 100
2019-03-05 12:31:27,377 -  nornir.core -    DEBUG -        run() - {'command_string': 'sh run | i CRC'}
2019-03-05 12:31:27,377 -  nornir.core -    DEBUG -        run() - {'command_string': 'sh run | i CRC'}
2019-03-05 12:33:15,509 -  nornir.core -     INFO -        run() - Running task 'netmiko_send_command' with num_workers: 100
2019-03-05 12:33:15,509 -  nornir.core -     INFO -        run() - Running task 'netmiko_send_command' with num_workers: 100
2019-03-05 12:33:15,509 -  nornir.core -    DEBUG -        run() - {'command_string': 'sh int status'}
2019-03-05 12:33:15,509 -  nornir.core -    DEBUG -        run() - {'command_string': 'sh int status'}
2019-03-05 12:33:15,543 - nornir.core.task -     INFO -      start() - GNS.CE1: netmiko_send_command: running task
2019-03-05 12:33:15,544 - nornir.core.task -     INFO -      start() - GNS.CE2: netmiko_send_command: running task
2019-03-05 12:33:15,544 - nornir.core.task -     INFO -      start() - GNS.CE2: netmiko_send_command: running task
2019-03-05 12:33:15,543 - nornir.core.task -     INFO -      start() - GNS.CE1: netmiko_send_command: running task
2019-03-05 12:33:15,544 - nornir.core.task -     INFO -      start() - GNS.CE3: netmiko_send_command: running task
2019-03-05 12:33:15,544 - nornir.core.task -     INFO -      start() - GNS.CE3: netmiko_send_command: running task
2019-03-05 12:33:15,548 - nornir.core.task -    ERROR -      start() - GNS.CE1: Traceback (most recent call last):
  File "C:\Users\m_buck\AppData\Local\Programs\Python\Python37-32\lib\site-packages\nornir\core\task.py", line 62, in start
    r = self.task(self, **self.params)
  File "C:\Users\m_buck\AppData\Local\Programs\Python\Python37-32\lib\site-packages\nornir\plugins\tasks\networking\netmiko_send_command.py", line 26, in netmiko_send_command
    net_connect = task.host.get_connection("netmiko", task.nornir.config)
  File "C:\Users\m_buck\AppData\Local\Programs\Python\Python37-32\lib\site-packages\nornir\core\inventory.py", line 297, in get_connection
    **self.get_connection_parameters(connection).dict(),
  File "C:\Users\m_buck\AppData\Local\Programs\Python\Python37-32\lib\site-packages\nornir\core\inventory.py", line 347, in open_connection
    configuration=configuration,
  File "C:\Users\m_buck\AppData\Local\Programs\Python\Python37-32\lib\site-packages\nornir\plugins\connections\netmiko.py", line 51, in open
    self.connection = ConnectHandler(**parameters)
  File "C:\Users\m_buck\AppData\Local\Programs\Python\Python37-32\lib\site-packages\netmiko\ssh_dispatcher.py", line 214, in ConnectHandler
    if kwargs['device_type'] not in platforms:
KeyError: 'device_type'

2019-03-05 12:33:15,548 - nornir.core.task -    ERROR -      start() - GNS.CE3: Traceback (most recent call last):
  File "C:\Users\m_buck\AppData\Local\Programs\Python\Python37-32\lib\site-packages\nornir\core\task.py", line 62, in start
    r = self.task(self, **self.params)
  File "C:\Users\m_buck\AppData\Local\Programs\Python\Python37-32\lib\site-packages\nornir\plugins\tasks\networking\netmiko_send_command.py", line 26, in netmiko_send_command
    net_connect = task.host.get_connection("netmiko", task.nornir.config)
  File "C:\Users\m_buck\AppData\Local\Programs\Python\Python37-32\lib\site-packages\nornir\core\inventory.py", line 297, in get_connection
    **self.get_connection_parameters(connection).dict(),
  File "C:\Users\m_buck\AppData\Local\Programs\Python\Python37-32\lib\site-packages\nornir\core\inventory.py", line 347, in open_connection
    configuration=configuration,
  File "C:\Users\m_buck\AppData\Local\Programs\Python\Python37-32\lib\site-packages\nornir\plugins\connections\netmiko.py", line 51, in open
    self.connection = ConnectHandler(**parameters)
  File "C:\Users\m_buck\AppData\Local\Programs\Python\Python37-32\lib\site-packages\netmiko\ssh_dispatcher.py", line 214, in ConnectHandler
    if kwargs['device_type'] not in platforms:
KeyError: 'device_type'

2019-03-05 12:33:15,548 - nornir.core.task -    ERROR -      start() - GNS.CE1: Traceback (most recent call last):
  File "C:\Users\m_buck\AppData\Local\Programs\Python\Python37-32\lib\site-packages\nornir\core\task.py", line 62, in start
    r = self.task(self, **self.params)
  File "C:\Users\m_buck\AppData\Local\Programs\Python\Python37-32\lib\site-packages\nornir\plugins\tasks\networking\netmiko_send_command.py", line 26, in netmiko_send_command
    net_connect = task.host.get_connection("netmiko", task.nornir.config)
  File "C:\Users\m_buck\AppData\Local\Programs\Python\Python37-32\lib\site-packages\nornir\core\inventory.py", line 297, in get_connection
    **self.get_connection_parameters(connection).dict(),
  File "C:\Users\m_buck\AppData\Local\Programs\Python\Python37-32\lib\site-packages\nornir\core\inventory.py", line 347, in open_connection
    configuration=configuration,
  File "C:\Users\m_buck\AppData\Local\Programs\Python\Python37-32\lib\site-packages\nornir\plugins\connections\netmiko.py", line 51, in open
    self.connection = ConnectHandler(**parameters)
  File "C:\Users\m_buck\AppData\Local\Programs\Python\Python37-32\lib\site-packages\netmiko\ssh_dispatcher.py", line 214, in ConnectHandler
    if kwargs['device_type'] not in platforms:
KeyError: 'device_type'

2019-03-05 12:33:15,548 - nornir.core.task -    ERROR -      start() - GNS.CE2: Traceback (most recent call last):
  File "C:\Users\m_buck\AppData\Local\Programs\Python\Python37-32\lib\site-packages\nornir\core\task.py", line 62, in start
    r = self.task(self, **self.params)
  File "C:\Users\m_buck\AppData\Local\Programs\Python\Python37-32\lib\site-packages\nornir\plugins\tasks\networking\netmiko_send_command.py", line 26, in netmiko_send_command
    net_connect = task.host.get_connection("netmiko", task.nornir.config)
  File "C:\Users\m_buck\AppData\Local\Programs\Python\Python37-32\lib\site-packages\nornir\core\inventory.py", line 297, in get_connection
    **self.get_connection_parameters(connection).dict(),
  File "C:\Users\m_buck\AppData\Local\Programs\Python\Python37-32\lib\site-packages\nornir\core\inventory.py", line 347, in open_connection
    configuration=configuration,
  File "C:\Users\m_buck\AppData\Local\Programs\Python\Python37-32\lib\site-packages\nornir\plugins\connections\netmiko.py", line 51, in open
    self.connection = ConnectHandler(**parameters)
  File "C:\Users\m_buck\AppData\Local\Programs\Python\Python37-32\lib\site-packages\netmiko\ssh_dispatcher.py", line 214, in ConnectHandler
    if kwargs['device_type'] not in platforms:
KeyError: 'device_type'

2019-03-05 12:33:15,548 - nornir.core.task -    ERROR -      start() - GNS.CE3: Traceback (most recent call last):
  File "C:\Users\m_buck\AppData\Local\Programs\Python\Python37-32\lib\site-packages\nornir\core\task.py", line 62, in start
    r = self.task(self, **self.params)
  File "C:\Users\m_buck\AppData\Local\Programs\Python\Python37-32\lib\site-packages\nornir\plugins\tasks\networking\netmiko_send_command.py", line 26, in netmiko_send_command
    net_connect = task.host.get_connection("netmiko", task.nornir.config)
  File "C:\Users\m_buck\AppData\Local\Programs\Python\Python37-32\lib\site-packages\nornir\core\inventory.py", line 297, in get_connection
    **self.get_connection_parameters(connection).dict(),
  File "C:\Users\m_buck\AppData\Local\Programs\Python\Python37-32\lib\site-packages\nornir\core\inventory.py", line 347, in open_connection
    configuration=configuration,
  File "C:\Users\m_buck\AppData\Local\Programs\Python\Python37-32\lib\site-packages\nornir\plugins\connections\netmiko.py", line 51, in open
    self.connection = ConnectHandler(**parameters)
  File "C:\Users\m_buck\AppData\Local\Programs\Python\Python37-32\lib\site-packages\netmiko\ssh_dispatcher.py", line 214, in ConnectHandler
    if kwargs['device_type'] not in platforms:
KeyError: 'device_type'

2019-03-05 12:33:15,548 - nornir.core.task -    ERROR -      start() - GNS.CE2: Traceback (most recent call last):
  File "C:\Users\m_buck\AppData\Local\Programs\Python\Python37-32\lib\site-packages\nornir\core\task.py", line 62, in start
    r = self.task(self, **self.params)
  File "C:\Users\m_buck\AppData\Local\Programs\Python\Python37-32\lib\site-packages\nornir\plugins\tasks\networking\netmiko_send_command.py", line 26, in netmiko_send_command
    net_connect = task.host.get_connection("netmiko", task.nornir.config)
  File "C:\Users\m_buck\AppData\Local\Programs\Python\Python37-32\lib\site-packages\nornir\core\inventory.py", line 297, in get_connection
    **self.get_connection_parameters(connection).dict(),
  File "C:\Users\m_buck\AppData\Local\Programs\Python\Python37-32\lib\site-packages\nornir\core\inventory.py", line 347, in open_connection
    configuration=configuration,
  File "C:\Users\m_buck\AppData\Local\Programs\Python\Python37-32\lib\site-packages\nornir\plugins\connections\netmiko.py", line 51, in open
    self.connection = ConnectHandler(**parameters)
  File "C:\Users\m_buck\AppData\Local\Programs\Python\Python37-32\lib\site-packages\netmiko\ssh_dispatcher.py", line 214, in ConnectHandler
    if kwargs['device_type'] not in platforms:
KeyError: 'device_type'

2019-03-05 12:33:15,651 -  nornir.core -     INFO -        run() - Running task 'netmiko_send_command' with num_workers: 100
2019-03-05 12:33:15,651 -  nornir.core -     INFO -        run() - Running task 'netmiko_send_command' with num_workers: 100
2019-03-05 12:33:15,651 -  nornir.core -    DEBUG -        run() - {'command_string': 'sh log'}
2019-03-05 12:33:15,651 -  nornir.core -    DEBUG -        run() - {'command_string': 'sh log'}
2019-03-05 12:33:15,775 -  nornir.core -     INFO -        run() - Running task 'netmiko_send_command' with num_workers: 100
2019-03-05 12:33:15,775 -  nornir.core -     INFO -        run() - Running task 'netmiko_send_command' with num_workers: 100
2019-03-05 12:33:15,776 -  nornir.core -    DEBUG -        run() - {'command_string': 'sh run | i CRC'}
2019-03-05 12:33:15,776 -  nornir.core -    DEBUG -        run() - {'command_string': 'sh run | i CRC'}
2019-03-05 12:52:59,300 -  nornir.core -     INFO -        run() - Running task 'netmiko_send_command' with num_workers: 100
2019-03-05 12:52:59,300 -  nornir.core -     INFO -        run() - Running task 'netmiko_send_command' with num_workers: 100
2019-03-05 12:52:59,301 -  nornir.core -    DEBUG -        run() - {'command_string': 'sh int status'}
2019-03-05 12:52:59,301 -  nornir.core -    DEBUG -        run() - {'command_string': 'sh int status'}
2019-03-05 12:52:59,336 - nornir.core.task -     INFO -      start() - GNS.CE1: netmiko_send_command: running task
2019-03-05 12:52:59,337 - nornir.core.task -     INFO -      start() - GNS.CE2: netmiko_send_command: running task
2019-03-05 12:52:59,337 - nornir.core.task -     INFO -      start() - GNS.CE3: netmiko_send_command: running task
2019-03-05 12:52:59,336 - nornir.core.task -     INFO -      start() - GNS.CE1: netmiko_send_command: running task
2019-03-05 12:52:59,337 - nornir.core.task -     INFO -      start() - GNS.CE2: netmiko_send_command: running task
2019-03-05 12:52:59,337 - nornir.core.task -     INFO -      start() - GNS.CE3: netmiko_send_command: running task
2019-03-05 12:52:59,340 - nornir.core.task -    ERROR -      start() - GNS.CE1: Traceback (most recent call last):
  File "C:\Users\m_buck\AppData\Local\Programs\Python\Python37-32\lib\site-packages\nornir\core\task.py", line 62, in start
    r = self.task(self, **self.params)
  File "C:\Users\m_buck\AppData\Local\Programs\Python\Python37-32\lib\site-packages\nornir\plugins\tasks\networking\netmiko_send_command.py", line 26, in netmiko_send_command
    net_connect = task.host.get_connection("netmiko", task.nornir.config)
  File "C:\Users\m_buck\AppData\Local\Programs\Python\Python37-32\lib\site-packages\nornir\core\inventory.py", line 297, in get_connection
    **self.get_connection_parameters(connection).dict(),
  File "C:\Users\m_buck\AppData\Local\Programs\Python\Python37-32\lib\site-packages\nornir\core\inventory.py", line 347, in open_connection
    configuration=configuration,
  File "C:\Users\m_buck\AppData\Local\Programs\Python\Python37-32\lib\site-packages\nornir\plugins\connections\netmiko.py", line 51, in open
    self.connection = ConnectHandler(**parameters)
  File "C:\Users\m_buck\AppData\Local\Programs\Python\Python37-32\lib\site-packages\netmiko\ssh_dispatcher.py", line 214, in ConnectHandler
    if kwargs['device_type'] not in platforms:
KeyError: 'device_type'

2019-03-05 12:52:59,340 - nornir.core.task -    ERROR -      start() - GNS.CE2: Traceback (most recent call last):
  File "C:\Users\m_buck\AppData\Local\Programs\Python\Python37-32\lib\site-packages\nornir\core\task.py", line 62, in start
    r = self.task(self, **self.params)
  File "C:\Users\m_buck\AppData\Local\Programs\Python\Python37-32\lib\site-packages\nornir\plugins\tasks\networking\netmiko_send_command.py", line 26, in netmiko_send_command
    net_connect = task.host.get_connection("netmiko", task.nornir.config)
  File "C:\Users\m_buck\AppData\Local\Programs\Python\Python37-32\lib\site-packages\nornir\core\inventory.py", line 297, in get_connection
    **self.get_connection_parameters(connection).dict(),
  File "C:\Users\m_buck\AppData\Local\Programs\Python\Python37-32\lib\site-packages\nornir\core\inventory.py", line 347, in open_connection
    configuration=configuration,
  File "C:\Users\m_buck\AppData\Local\Programs\Python\Python37-32\lib\site-packages\nornir\plugins\connections\netmiko.py", line 51, in open
    self.connection = ConnectHandler(**parameters)
  File "C:\Users\m_buck\AppData\Local\Programs\Python\Python37-32\lib\site-packages\netmiko\ssh_dispatcher.py", line 214, in ConnectHandler
    if kwargs['device_type'] not in platforms:
KeyError: 'device_type'

2019-03-05 12:52:59,340 - nornir.core.task -    ERROR -      start() - GNS.CE1: Traceback (most recent call last):
  File "C:\Users\m_buck\AppData\Local\Programs\Python\Python37-32\lib\site-packages\nornir\core\task.py", line 62, in start
    r = self.task(self, **self.params)
  File "C:\Users\m_buck\AppData\Local\Programs\Python\Python37-32\lib\site-packages\nornir\plugins\tasks\networking\netmiko_send_command.py", line 26, in netmiko_send_command
    net_connect = task.host.get_connection("netmiko", task.nornir.config)
  File "C:\Users\m_buck\AppData\Local\Programs\Python\Python37-32\lib\site-packages\nornir\core\inventory.py", line 297, in get_connection
    **self.get_connection_parameters(connection).dict(),
  File "C:\Users\m_buck\AppData\Local\Programs\Python\Python37-32\lib\site-packages\nornir\core\inventory.py", line 347, in open_connection
    configuration=configuration,
  File "C:\Users\m_buck\AppData\Local\Programs\Python\Python37-32\lib\site-packages\nornir\plugins\connections\netmiko.py", line 51, in open
    self.connection = ConnectHandler(**parameters)
  File "C:\Users\m_buck\AppData\Local\Programs\Python\Python37-32\lib\site-packages\netmiko\ssh_dispatcher.py", line 214, in ConnectHandler
    if kwargs['device_type'] not in platforms:
KeyError: 'device_type'

2019-03-05 12:52:59,341 - nornir.core.task -    ERROR -      start() - GNS.CE3: Traceback (most recent call last):
  File "C:\Users\m_buck\AppData\Local\Programs\Python\Python37-32\lib\site-packages\nornir\core\task.py", line 62, in start
    r = self.task(self, **self.params)
  File "C:\Users\m_buck\AppData\Local\Programs\Python\Python37-32\lib\site-packages\nornir\plugins\tasks\networking\netmiko_send_command.py", line 26, in netmiko_send_command
    net_connect = task.host.get_connection("netmiko", task.nornir.config)
  File "C:\Users\m_buck\AppData\Local\Programs\Python\Python37-32\lib\site-packages\nornir\core\inventory.py", line 297, in get_connection
    **self.get_connection_parameters(connection).dict(),
  File "C:\Users\m_buck\AppData\Local\Programs\Python\Python37-32\lib\site-packages\nornir\core\inventory.py", line 347, in open_connection
    configuration=configuration,
  File "C:\Users\m_buck\AppData\Local\Programs\Python\Python37-32\lib\site-packages\nornir\plugins\connections\netmiko.py", line 51, in open
    self.connection = ConnectHandler(**parameters)
  File "C:\Users\m_buck\AppData\Local\Programs\Python\Python37-32\lib\site-packages\netmiko\ssh_dispatcher.py", line 214, in ConnectHandler
    if kwargs['device_type'] not in platforms:
KeyError: 'device_type'

2019-03-05 12:52:59,340 - nornir.core.task -    ERROR -      start() - GNS.CE2: Traceback (most recent call last):
  File "C:\Users\m_buck\AppData\Local\Programs\Python\Python37-32\lib\site-packages\nornir\core\task.py", line 62, in start
    r = self.task(self, **self.params)
  File "C:\Users\m_buck\AppData\Local\Programs\Python\Python37-32\lib\site-packages\nornir\plugins\tasks\networking\netmiko_send_command.py", line 26, in netmiko_send_command
    net_connect = task.host.get_connection("netmiko", task.nornir.config)
  File "C:\Users\m_buck\AppData\Local\Programs\Python\Python37-32\lib\site-packages\nornir\core\inventory.py", line 297, in get_connection
    **self.get_connection_parameters(connection).dict(),
  File "C:\Users\m_buck\AppData\Local\Programs\Python\Python37-32\lib\site-packages\nornir\core\inventory.py", line 347, in open_connection
    configuration=configuration,
  File "C:\Users\m_buck\AppData\Local\Programs\Python\Python37-32\lib\site-packages\nornir\plugins\connections\netmiko.py", line 51, in open
    self.connection = ConnectHandler(**parameters)
  File "C:\Users\m_buck\AppData\Local\Programs\Python\Python37-32\lib\site-packages\netmiko\ssh_dispatcher.py", line 214, in ConnectHandler
    if kwargs['device_type'] not in platforms:
KeyError: 'device_type'

2019-03-05 12:52:59,341 - nornir.core.task -    ERROR -      start() - GNS.CE3: Traceback (most recent call last):
  File "C:\Users\m_buck\AppData\Local\Programs\Python\Python37-32\lib\site-packages\nornir\core\task.py", line 62, in start
    r = self.task(self, **self.params)
  File "C:\Users\m_buck\AppData\Local\Programs\Python\Python37-32\lib\site-packages\nornir\plugins\tasks\networking\netmiko_send_command.py", line 26, in netmiko_send_command
    net_connect = task.host.get_connection("netmiko", task.nornir.config)
  File "C:\Users\m_buck\AppData\Local\Programs\Python\Python37-32\lib\site-packages\nornir\core\inventory.py", line 297, in get_connection
    **self.get_connection_parameters(connection).dict(),
  File "C:\Users\m_buck\AppData\Local\Programs\Python\Python37-32\lib\site-packages\nornir\core\inventory.py", line 347, in open_connection
    configuration=configuration,
  File "C:\Users\m_buck\AppData\Local\Programs\Python\Python37-32\lib\site-packages\nornir\plugins\connections\netmiko.py", line 51, in open
    self.connection = ConnectHandler(**parameters)
  File "C:\Users\m_buck\AppData\Local\Programs\Python\Python37-32\lib\site-packages\netmiko\ssh_dispatcher.py", line 214, in ConnectHandler
    if kwargs['device_type'] not in platforms:
KeyError: 'device_type'

2019-03-05 12:52:59,445 -  nornir.core -     INFO -        run() - Running task 'netmiko_send_command' with num_workers: 100
2019-03-05 12:52:59,445 -  nornir.core -     INFO -        run() - Running task 'netmiko_send_command' with num_workers: 100
2019-03-05 12:52:59,445 -  nornir.core -    DEBUG -        run() - {'command_string': 'sh log'}
2019-03-05 12:52:59,445 -  nornir.core -    DEBUG -        run() - {'command_string': 'sh log'}
2019-03-05 12:52:59,571 -  nornir.core -     INFO -        run() - Running task 'netmiko_send_command' with num_workers: 100
2019-03-05 12:52:59,571 -  nornir.core -     INFO -        run() - Running task 'netmiko_send_command' with num_workers: 100
2019-03-05 12:52:59,571 -  nornir.core -    DEBUG -        run() - {'command_string': 'sh run | i CRC'}
2019-03-05 12:52:59,571 -  nornir.core -    DEBUG -        run() - {'command_string': 'sh run | i CRC'}
2019-03-05 12:53:25,574 -  nornir.core -     INFO -        run() - Running task 'netmiko_send_command' with num_workers: 100
2019-03-05 12:53:25,574 -  nornir.core -     INFO -        run() - Running task 'netmiko_send_command' with num_workers: 100
2019-03-05 12:53:25,574 -  nornir.core -    DEBUG -        run() - {'command_string': 'sh int status'}
2019-03-05 12:53:25,574 -  nornir.core -    DEBUG -        run() - {'command_string': 'sh int status'}
2019-03-05 12:53:25,606 - nornir.core.task -     INFO -      start() - GNS.CE1: netmiko_send_command: running task
2019-03-05 12:53:25,606 - nornir.core.task -     INFO -      start() - GNS.CE2: netmiko_send_command: running task
2019-03-05 12:53:25,606 - nornir.core.task -     INFO -      start() - GNS.CE2: netmiko_send_command: running task
2019-03-05 12:53:25,606 - nornir.core.task -     INFO -      start() - GNS.CE1: netmiko_send_command: running task
2019-03-05 12:53:25,606 - nornir.core.task -     INFO -      start() - GNS.CE3: netmiko_send_command: running task
2019-03-05 12:53:25,606 - nornir.core.task -     INFO -      start() - GNS.CE3: netmiko_send_command: running task
2019-03-05 12:53:25,610 - nornir.core.task -    ERROR -      start() - GNS.CE1: Traceback (most recent call last):
  File "C:\Users\m_buck\AppData\Local\Programs\Python\Python37-32\lib\site-packages\nornir\core\task.py", line 62, in start
    r = self.task(self, **self.params)
  File "C:\Users\m_buck\AppData\Local\Programs\Python\Python37-32\lib\site-packages\nornir\plugins\tasks\networking\netmiko_send_command.py", line 26, in netmiko_send_command
    net_connect = task.host.get_connection("netmiko", task.nornir.config)
  File "C:\Users\m_buck\AppData\Local\Programs\Python\Python37-32\lib\site-packages\nornir\core\inventory.py", line 297, in get_connection
    **self.get_connection_parameters(connection).dict(),
  File "C:\Users\m_buck\AppData\Local\Programs\Python\Python37-32\lib\site-packages\nornir\core\inventory.py", line 347, in open_connection
    configuration=configuration,
  File "C:\Users\m_buck\AppData\Local\Programs\Python\Python37-32\lib\site-packages\nornir\plugins\connections\netmiko.py", line 51, in open
    self.connection = ConnectHandler(**parameters)
  File "C:\Users\m_buck\AppData\Local\Programs\Python\Python37-32\lib\site-packages\netmiko\ssh_dispatcher.py", line 214, in ConnectHandler
    if kwargs['device_type'] not in platforms:
KeyError: 'device_type'

2019-03-05 12:53:25,610 - nornir.core.task -    ERROR -      start() - GNS.CE1: Traceback (most recent call last):
  File "C:\Users\m_buck\AppData\Local\Programs\Python\Python37-32\lib\site-packages\nornir\core\task.py", line 62, in start
    r = self.task(self, **self.params)
  File "C:\Users\m_buck\AppData\Local\Programs\Python\Python37-32\lib\site-packages\nornir\plugins\tasks\networking\netmiko_send_command.py", line 26, in netmiko_send_command
    net_connect = task.host.get_connection("netmiko", task.nornir.config)
  File "C:\Users\m_buck\AppData\Local\Programs\Python\Python37-32\lib\site-packages\nornir\core\inventory.py", line 297, in get_connection
    **self.get_connection_parameters(connection).dict(),
  File "C:\Users\m_buck\AppData\Local\Programs\Python\Python37-32\lib\site-packages\nornir\core\inventory.py", line 347, in open_connection
    configuration=configuration,
  File "C:\Users\m_buck\AppData\Local\Programs\Python\Python37-32\lib\site-packages\nornir\plugins\connections\netmiko.py", line 51, in open
    self.connection = ConnectHandler(**parameters)
  File "C:\Users\m_buck\AppData\Local\Programs\Python\Python37-32\lib\site-packages\netmiko\ssh_dispatcher.py", line 214, in ConnectHandler
    if kwargs['device_type'] not in platforms:
KeyError: 'device_type'

2019-03-05 12:53:25,610 - nornir.core.task -    ERROR -      start() - GNS.CE3: Traceback (most recent call last):
  File "C:\Users\m_buck\AppData\Local\Programs\Python\Python37-32\lib\site-packages\nornir\core\task.py", line 62, in start
    r = self.task(self, **self.params)
  File "C:\Users\m_buck\AppData\Local\Programs\Python\Python37-32\lib\site-packages\nornir\plugins\tasks\networking\netmiko_send_command.py", line 26, in netmiko_send_command
    net_connect = task.host.get_connection("netmiko", task.nornir.config)
  File "C:\Users\m_buck\AppData\Local\Programs\Python\Python37-32\lib\site-packages\nornir\core\inventory.py", line 297, in get_connection
    **self.get_connection_parameters(connection).dict(),
  File "C:\Users\m_buck\AppData\Local\Programs\Python\Python37-32\lib\site-packages\nornir\core\inventory.py", line 347, in open_connection
    configuration=configuration,
  File "C:\Users\m_buck\AppData\Local\Programs\Python\Python37-32\lib\site-packages\nornir\plugins\connections\netmiko.py", line 51, in open
    self.connection = ConnectHandler(**parameters)
  File "C:\Users\m_buck\AppData\Local\Programs\Python\Python37-32\lib\site-packages\netmiko\ssh_dispatcher.py", line 214, in ConnectHandler
    if kwargs['device_type'] not in platforms:
KeyError: 'device_type'

2019-03-05 12:53:25,611 - nornir.core.task -    ERROR -      start() - GNS.CE2: Traceback (most recent call last):
  File "C:\Users\m_buck\AppData\Local\Programs\Python\Python37-32\lib\site-packages\nornir\core\task.py", line 62, in start
    r = self.task(self, **self.params)
  File "C:\Users\m_buck\AppData\Local\Programs\Python\Python37-32\lib\site-packages\nornir\plugins\tasks\networking\netmiko_send_command.py", line 26, in netmiko_send_command
    net_connect = task.host.get_connection("netmiko", task.nornir.config)
  File "C:\Users\m_buck\AppData\Local\Programs\Python\Python37-32\lib\site-packages\nornir\core\inventory.py", line 297, in get_connection
    **self.get_connection_parameters(connection).dict(),
  File "C:\Users\m_buck\AppData\Local\Programs\Python\Python37-32\lib\site-packages\nornir\core\inventory.py", line 347, in open_connection
    configuration=configuration,
  File "C:\Users\m_buck\AppData\Local\Programs\Python\Python37-32\lib\site-packages\nornir\plugins\connections\netmiko.py", line 51, in open
    self.connection = ConnectHandler(**parameters)
  File "C:\Users\m_buck\AppData\Local\Programs\Python\Python37-32\lib\site-packages\netmiko\ssh_dispatcher.py", line 214, in ConnectHandler
    if kwargs['device_type'] not in platforms:
KeyError: 'device_type'

2019-03-05 12:53:25,610 - nornir.core.task -    ERROR -      start() - GNS.CE3: Traceback (most recent call last):
  File "C:\Users\m_buck\AppData\Local\Programs\Python\Python37-32\lib\site-packages\nornir\core\task.py", line 62, in start
    r = self.task(self, **self.params)
  File "C:\Users\m_buck\AppData\Local\Programs\Python\Python37-32\lib\site-packages\nornir\plugins\tasks\networking\netmiko_send_command.py", line 26, in netmiko_send_command
    net_connect = task.host.get_connection("netmiko", task.nornir.config)
  File "C:\Users\m_buck\AppData\Local\Programs\Python\Python37-32\lib\site-packages\nornir\core\inventory.py", line 297, in get_connection
    **self.get_connection_parameters(connection).dict(),
  File "C:\Users\m_buck\AppData\Local\Programs\Python\Python37-32\lib\site-packages\nornir\core\inventory.py", line 347, in open_connection
    configuration=configuration,
  File "C:\Users\m_buck\AppData\Local\Programs\Python\Python37-32\lib\site-packages\nornir\plugins\connections\netmiko.py", line 51, in open
    self.connection = ConnectHandler(**parameters)
  File "C:\Users\m_buck\AppData\Local\Programs\Python\Python37-32\lib\site-packages\netmiko\ssh_dispatcher.py", line 214, in ConnectHandler
    if kwargs['device_type'] not in platforms:
KeyError: 'device_type'

2019-03-05 12:53:25,611 - nornir.core.task -    ERROR -      start() - GNS.CE2: Traceback (most recent call last):
  File "C:\Users\m_buck\AppData\Local\Programs\Python\Python37-32\lib\site-packages\nornir\core\task.py", line 62, in start
    r = self.task(self, **self.params)
  File "C:\Users\m_buck\AppData\Local\Programs\Python\Python37-32\lib\site-packages\nornir\plugins\tasks\networking\netmiko_send_command.py", line 26, in netmiko_send_command
    net_connect = task.host.get_connection("netmiko", task.nornir.config)
  File "C:\Users\m_buck\AppData\Local\Programs\Python\Python37-32\lib\site-packages\nornir\core\inventory.py", line 297, in get_connection
    **self.get_connection_parameters(connection).dict(),
  File "C:\Users\m_buck\AppData\Local\Programs\Python\Python37-32\lib\site-packages\nornir\core\inventory.py", line 347, in open_connection
    configuration=configuration,
  File "C:\Users\m_buck\AppData\Local\Programs\Python\Python37-32\lib\site-packages\nornir\plugins\connections\netmiko.py", line 51, in open
    self.connection = ConnectHandler(**parameters)
  File "C:\Users\m_buck\AppData\Local\Programs\Python\Python37-32\lib\site-packages\netmiko\ssh_dispatcher.py", line 214, in ConnectHandler
    if kwargs['device_type'] not in platforms:
KeyError: 'device_type'

2019-03-05 12:53:25,715 -  nornir.core -     INFO -        run() - Running task 'netmiko_send_command' with num_workers: 100
2019-03-05 12:53:25,715 -  nornir.core -     INFO -        run() - Running task 'netmiko_send_command' with num_workers: 100
2019-03-05 12:53:25,715 -  nornir.core -    DEBUG -        run() - {'command_string': 'sh log'}
2019-03-05 12:53:25,715 -  nornir.core -    DEBUG -        run() - {'command_string': 'sh log'}
2019-03-05 12:53:25,837 -  nornir.core -     INFO -        run() - Running task 'netmiko_send_command' with num_workers: 100
2019-03-05 12:53:25,837 -  nornir.core -     INFO -        run() - Running task 'netmiko_send_command' with num_workers: 100
2019-03-05 12:53:25,838 -  nornir.core -    DEBUG -        run() - {'command_string': 'sh run | i CRC'}
2019-03-05 12:53:25,838 -  nornir.core -    DEBUG -        run() - {'command_string': 'sh run | i CRC'}
2019-03-05 16:55:59,553 -  nornir.core -     INFO -        run() - Running task 'netmiko_send_command' with num_workers: 100
2019-03-05 16:55:59,553 -  nornir.core -     INFO -        run() - Running task 'netmiko_send_command' with num_workers: 100
2019-03-05 16:55:59,553 -  nornir.core -    DEBUG -        run() - {'command_string': 'sh int status'}
2019-03-05 16:55:59,553 -  nornir.core -    DEBUG -        run() - {'command_string': 'sh int status'}
2019-03-05 16:55:59,595 - nornir.core.task -     INFO -      start() - GNS.CE1: netmiko_send_command: running task
2019-03-05 16:55:59,595 - nornir.core.task -     INFO -      start() - GNS.CE1: netmiko_send_command: running task
2019-03-05 16:55:59,595 - nornir.core.task -     INFO -      start() - GNS.CE3: netmiko_send_command: running task
2019-03-05 16:55:59,595 - nornir.core.task -     INFO -      start() - GNS.CE3: netmiko_send_command: running task
2019-03-05 16:55:59,595 - nornir.core.task -     INFO -      start() - GNS.CE2: netmiko_send_command: running task
2019-03-05 16:55:59,595 - nornir.core.task -     INFO -      start() - GNS.CE2: netmiko_send_command: running task
2019-03-05 16:55:59,601 - nornir.core.task -    ERROR -      start() - GNS.CE3: Traceback (most recent call last):
  File "C:\Users\m_buck\AppData\Local\Programs\Python\Python37-32\lib\site-packages\nornir\core\task.py", line 62, in start
    r = self.task(self, **self.params)
  File "C:\Users\m_buck\AppData\Local\Programs\Python\Python37-32\lib\site-packages\nornir\plugins\tasks\networking\netmiko_send_command.py", line 26, in netmiko_send_command
    net_connect = task.host.get_connection("netmiko", task.nornir.config)
  File "C:\Users\m_buck\AppData\Local\Programs\Python\Python37-32\lib\site-packages\nornir\core\inventory.py", line 297, in get_connection
    **self.get_connection_parameters(connection).dict(),
  File "C:\Users\m_buck\AppData\Local\Programs\Python\Python37-32\lib\site-packages\nornir\core\inventory.py", line 347, in open_connection
    configuration=configuration,
  File "C:\Users\m_buck\AppData\Local\Programs\Python\Python37-32\lib\site-packages\nornir\plugins\connections\netmiko.py", line 51, in open
    self.connection = ConnectHandler(**parameters)
  File "C:\Users\m_buck\AppData\Local\Programs\Python\Python37-32\lib\site-packages\netmiko\ssh_dispatcher.py", line 214, in ConnectHandler
    if kwargs['device_type'] not in platforms:
KeyError: 'device_type'

2019-03-05 16:55:59,601 - nornir.core.task -    ERROR -      start() - GNS.CE2: Traceback (most recent call last):
  File "C:\Users\m_buck\AppData\Local\Programs\Python\Python37-32\lib\site-packages\nornir\core\task.py", line 62, in start
    r = self.task(self, **self.params)
  File "C:\Users\m_buck\AppData\Local\Programs\Python\Python37-32\lib\site-packages\nornir\plugins\tasks\networking\netmiko_send_command.py", line 26, in netmiko_send_command
    net_connect = task.host.get_connection("netmiko", task.nornir.config)
  File "C:\Users\m_buck\AppData\Local\Programs\Python\Python37-32\lib\site-packages\nornir\core\inventory.py", line 297, in get_connection
    **self.get_connection_parameters(connection).dict(),
  File "C:\Users\m_buck\AppData\Local\Programs\Python\Python37-32\lib\site-packages\nornir\core\inventory.py", line 347, in open_connection
    configuration=configuration,
  File "C:\Users\m_buck\AppData\Local\Programs\Python\Python37-32\lib\site-packages\nornir\plugins\connections\netmiko.py", line 51, in open
    self.connection = ConnectHandler(**parameters)
  File "C:\Users\m_buck\AppData\Local\Programs\Python\Python37-32\lib\site-packages\netmiko\ssh_dispatcher.py", line 214, in ConnectHandler
    if kwargs['device_type'] not in platforms:
KeyError: 'device_type'

2019-03-05 16:55:59,601 - nornir.core.task -    ERROR -      start() - GNS.CE2: Traceback (most recent call last):
  File "C:\Users\m_buck\AppData\Local\Programs\Python\Python37-32\lib\site-packages\nornir\core\task.py", line 62, in start
    r = self.task(self, **self.params)
  File "C:\Users\m_buck\AppData\Local\Programs\Python\Python37-32\lib\site-packages\nornir\plugins\tasks\networking\netmiko_send_command.py", line 26, in netmiko_send_command
    net_connect = task.host.get_connection("netmiko", task.nornir.config)
  File "C:\Users\m_buck\AppData\Local\Programs\Python\Python37-32\lib\site-packages\nornir\core\inventory.py", line 297, in get_connection
    **self.get_connection_parameters(connection).dict(),
  File "C:\Users\m_buck\AppData\Local\Programs\Python\Python37-32\lib\site-packages\nornir\core\inventory.py", line 347, in open_connection
    configuration=configuration,
  File "C:\Users\m_buck\AppData\Local\Programs\Python\Python37-32\lib\site-packages\nornir\plugins\connections\netmiko.py", line 51, in open
    self.connection = ConnectHandler(**parameters)
  File "C:\Users\m_buck\AppData\Local\Programs\Python\Python37-32\lib\site-packages\netmiko\ssh_dispatcher.py", line 214, in ConnectHandler
    if kwargs['device_type'] not in platforms:
KeyError: 'device_type'

2019-03-05 16:55:59,601 - nornir.core.task -    ERROR -      start() - GNS.CE3: Traceback (most recent call last):
  File "C:\Users\m_buck\AppData\Local\Programs\Python\Python37-32\lib\site-packages\nornir\core\task.py", line 62, in start
    r = self.task(self, **self.params)
  File "C:\Users\m_buck\AppData\Local\Programs\Python\Python37-32\lib\site-packages\nornir\plugins\tasks\networking\netmiko_send_command.py", line 26, in netmiko_send_command
    net_connect = task.host.get_connection("netmiko", task.nornir.config)
  File "C:\Users\m_buck\AppData\Local\Programs\Python\Python37-32\lib\site-packages\nornir\core\inventory.py", line 297, in get_connection
    **self.get_connection_parameters(connection).dict(),
  File "C:\Users\m_buck\AppData\Local\Programs\Python\Python37-32\lib\site-packages\nornir\core\inventory.py", line 347, in open_connection
    configuration=configuration,
  File "C:\Users\m_buck\AppData\Local\Programs\Python\Python37-32\lib\site-packages\nornir\plugins\connections\netmiko.py", line 51, in open
    self.connection = ConnectHandler(**parameters)
  File "C:\Users\m_buck\AppData\Local\Programs\Python\Python37-32\lib\site-packages\netmiko\ssh_dispatcher.py", line 214, in ConnectHandler
    if kwargs['device_type'] not in platforms:
KeyError: 'device_type'

2019-03-05 16:55:59,601 - nornir.core.task -    ERROR -      start() - GNS.CE1: Traceback (most recent call last):
  File "C:\Users\m_buck\AppData\Local\Programs\Python\Python37-32\lib\site-packages\nornir\core\task.py", line 62, in start
    r = self.task(self, **self.params)
  File "C:\Users\m_buck\AppData\Local\Programs\Python\Python37-32\lib\site-packages\nornir\plugins\tasks\networking\netmiko_send_command.py", line 26, in netmiko_send_command
    net_connect = task.host.get_connection("netmiko", task.nornir.config)
  File "C:\Users\m_buck\AppData\Local\Programs\Python\Python37-32\lib\site-packages\nornir\core\inventory.py", line 297, in get_connection
    **self.get_connection_parameters(connection).dict(),
  File "C:\Users\m_buck\AppData\Local\Programs\Python\Python37-32\lib\site-packages\nornir\core\inventory.py", line 347, in open_connection
    configuration=configuration,
  File "C:\Users\m_buck\AppData\Local\Programs\Python\Python37-32\lib\site-packages\nornir\plugins\connections\netmiko.py", line 51, in open
    self.connection = ConnectHandler(**parameters)
  File "C:\Users\m_buck\AppData\Local\Programs\Python\Python37-32\lib\site-packages\netmiko\ssh_dispatcher.py", line 214, in ConnectHandler
    if kwargs['device_type'] not in platforms:
KeyError: 'device_type'

2019-03-05 16:55:59,601 - nornir.core.task -    ERROR -      start() - GNS.CE1: Traceback (most recent call last):
  File "C:\Users\m_buck\AppData\Local\Programs\Python\Python37-32\lib\site-packages\nornir\core\task.py", line 62, in start
    r = self.task(self, **self.params)
  File "C:\Users\m_buck\AppData\Local\Programs\Python\Python37-32\lib\site-packages\nornir\plugins\tasks\networking\netmiko_send_command.py", line 26, in netmiko_send_command
    net_connect = task.host.get_connection("netmiko", task.nornir.config)
  File "C:\Users\m_buck\AppData\Local\Programs\Python\Python37-32\lib\site-packages\nornir\core\inventory.py", line 297, in get_connection
    **self.get_connection_parameters(connection).dict(),
  File "C:\Users\m_buck\AppData\Local\Programs\Python\Python37-32\lib\site-packages\nornir\core\inventory.py", line 347, in open_connection
    configuration=configuration,
  File "C:\Users\m_buck\AppData\Local\Programs\Python\Python37-32\lib\site-packages\nornir\plugins\connections\netmiko.py", line 51, in open
    self.connection = ConnectHandler(**parameters)
  File "C:\Users\m_buck\AppData\Local\Programs\Python\Python37-32\lib\site-packages\netmiko\ssh_dispatcher.py", line 214, in ConnectHandler
    if kwargs['device_type'] not in platforms:
KeyError: 'device_type'

2019-03-05 16:55:59,706 -  nornir.core -     INFO -        run() - Running task 'netmiko_send_command' with num_workers: 100
2019-03-05 16:55:59,706 -  nornir.core -     INFO -        run() - Running task 'netmiko_send_command' with num_workers: 100
2019-03-05 16:55:59,706 -  nornir.core -    DEBUG -        run() - {'command_string': 'sh log'}
2019-03-05 16:55:59,706 -  nornir.core -    DEBUG -        run() - {'command_string': 'sh log'}
2019-03-05 16:55:59,828 -  nornir.core -     INFO -        run() - Running task 'netmiko_send_command' with num_workers: 100
2019-03-05 16:55:59,828 -  nornir.core -     INFO -        run() - Running task 'netmiko_send_command' with num_workers: 100
2019-03-05 16:55:59,828 -  nornir.core -    DEBUG -        run() - {'command_string': 'sh run | i CRC'}
2019-03-05 16:55:59,828 -  nornir.core -    DEBUG -        run() - {'command_string': 'sh run | i CRC'}
2019-03-06 09:47:31,023 -  nornir.core -     INFO -        run() - Running task 'netmiko_send_command' with num_workers: 100
2019-03-06 09:47:31,023 -  nornir.core -     INFO -        run() - Running task 'netmiko_send_command' with num_workers: 100
2019-03-06 09:47:31,024 -  nornir.core -    DEBUG -        run() - {'command_string': 'sh int status'}
2019-03-06 09:47:31,024 -  nornir.core -    DEBUG -        run() - {'command_string': 'sh int status'}
2019-03-06 09:47:31,073 - nornir.core.task -     INFO -      start() - GNS.CE1: netmiko_send_command: running task
2019-03-06 09:47:31,073 - nornir.core.task -     INFO -      start() - GNS.CE2: netmiko_send_command: running task
2019-03-06 09:47:31,073 - nornir.core.task -     INFO -      start() - GNS.CE2: netmiko_send_command: running task
2019-03-06 09:47:31,073 - nornir.core.task -     INFO -      start() - GNS.CE1: netmiko_send_command: running task
2019-03-06 09:47:31,073 - nornir.core.task -     INFO -      start() - GNS.CE3: netmiko_send_command: running task
2019-03-06 09:47:31,073 - nornir.core.task -     INFO -      start() - GNS.CE3: netmiko_send_command: running task
2019-03-06 09:47:31,125 - nornir.core.task -    ERROR -      start() - GNS.CE2: Traceback (most recent call last):
  File "C:\Users\m_buck\AppData\Local\Programs\Python\Python37-32\lib\site-packages\nornir\core\task.py", line 62, in start
    r = self.task(self, **self.params)
  File "C:\Users\m_buck\AppData\Local\Programs\Python\Python37-32\lib\site-packages\nornir\plugins\tasks\networking\netmiko_send_command.py", line 26, in netmiko_send_command
    net_connect = task.host.get_connection("netmiko", task.nornir.config)
  File "C:\Users\m_buck\AppData\Local\Programs\Python\Python37-32\lib\site-packages\nornir\core\inventory.py", line 297, in get_connection
    **self.get_connection_parameters(connection).dict(),
  File "C:\Users\m_buck\AppData\Local\Programs\Python\Python37-32\lib\site-packages\nornir\core\inventory.py", line 347, in open_connection
    configuration=configuration,
  File "C:\Users\m_buck\AppData\Local\Programs\Python\Python37-32\lib\site-packages\nornir\plugins\connections\netmiko.py", line 51, in open
    self.connection = ConnectHandler(**parameters)
  File "C:\Users\m_buck\AppData\Local\Programs\Python\Python37-32\lib\site-packages\netmiko\ssh_dispatcher.py", line 214, in ConnectHandler
    if kwargs['device_type'] not in platforms:
KeyError: 'device_type'

2019-03-06 09:47:31,125 - nornir.core.task -    ERROR -      start() - GNS.CE2: Traceback (most recent call last):
  File "C:\Users\m_buck\AppData\Local\Programs\Python\Python37-32\lib\site-packages\nornir\core\task.py", line 62, in start
    r = self.task(self, **self.params)
  File "C:\Users\m_buck\AppData\Local\Programs\Python\Python37-32\lib\site-packages\nornir\plugins\tasks\networking\netmiko_send_command.py", line 26, in netmiko_send_command
    net_connect = task.host.get_connection("netmiko", task.nornir.config)
  File "C:\Users\m_buck\AppData\Local\Programs\Python\Python37-32\lib\site-packages\nornir\core\inventory.py", line 297, in get_connection
    **self.get_connection_parameters(connection).dict(),
  File "C:\Users\m_buck\AppData\Local\Programs\Python\Python37-32\lib\site-packages\nornir\core\inventory.py", line 347, in open_connection
    configuration=configuration,
  File "C:\Users\m_buck\AppData\Local\Programs\Python\Python37-32\lib\site-packages\nornir\plugins\connections\netmiko.py", line 51, in open
    self.connection = ConnectHandler(**parameters)
  File "C:\Users\m_buck\AppData\Local\Programs\Python\Python37-32\lib\site-packages\netmiko\ssh_dispatcher.py", line 214, in ConnectHandler
    if kwargs['device_type'] not in platforms:
KeyError: 'device_type'

2019-03-06 09:47:31,125 - nornir.core.task -    ERROR -      start() - GNS.CE3: Traceback (most recent call last):
  File "C:\Users\m_buck\AppData\Local\Programs\Python\Python37-32\lib\site-packages\nornir\core\task.py", line 62, in start
    r = self.task(self, **self.params)
  File "C:\Users\m_buck\AppData\Local\Programs\Python\Python37-32\lib\site-packages\nornir\plugins\tasks\networking\netmiko_send_command.py", line 26, in netmiko_send_command
    net_connect = task.host.get_connection("netmiko", task.nornir.config)
  File "C:\Users\m_buck\AppData\Local\Programs\Python\Python37-32\lib\site-packages\nornir\core\inventory.py", line 297, in get_connection
    **self.get_connection_parameters(connection).dict(),
  File "C:\Users\m_buck\AppData\Local\Programs\Python\Python37-32\lib\site-packages\nornir\core\inventory.py", line 347, in open_connection
    configuration=configuration,
  File "C:\Users\m_buck\AppData\Local\Programs\Python\Python37-32\lib\site-packages\nornir\plugins\connections\netmiko.py", line 51, in open
    self.connection = ConnectHandler(**parameters)
  File "C:\Users\m_buck\AppData\Local\Programs\Python\Python37-32\lib\site-packages\netmiko\ssh_dispatcher.py", line 214, in ConnectHandler
    if kwargs['device_type'] not in platforms:
KeyError: 'device_type'

2019-03-06 09:47:31,125 - nornir.core.task -    ERROR -      start() - GNS.CE3: Traceback (most recent call last):
  File "C:\Users\m_buck\AppData\Local\Programs\Python\Python37-32\lib\site-packages\nornir\core\task.py", line 62, in start
    r = self.task(self, **self.params)
  File "C:\Users\m_buck\AppData\Local\Programs\Python\Python37-32\lib\site-packages\nornir\plugins\tasks\networking\netmiko_send_command.py", line 26, in netmiko_send_command
    net_connect = task.host.get_connection("netmiko", task.nornir.config)
  File "C:\Users\m_buck\AppData\Local\Programs\Python\Python37-32\lib\site-packages\nornir\core\inventory.py", line 297, in get_connection
    **self.get_connection_parameters(connection).dict(),
  File "C:\Users\m_buck\AppData\Local\Programs\Python\Python37-32\lib\site-packages\nornir\core\inventory.py", line 347, in open_connection
    configuration=configuration,
  File "C:\Users\m_buck\AppData\Local\Programs\Python\Python37-32\lib\site-packages\nornir\plugins\connections\netmiko.py", line 51, in open
    self.connection = ConnectHandler(**parameters)
  File "C:\Users\m_buck\AppData\Local\Programs\Python\Python37-32\lib\site-packages\netmiko\ssh_dispatcher.py", line 214, in ConnectHandler
    if kwargs['device_type'] not in platforms:
KeyError: 'device_type'

2019-03-06 09:47:31,126 - nornir.core.task -    ERROR -      start() - GNS.CE1: Traceback (most recent call last):
  File "C:\Users\m_buck\AppData\Local\Programs\Python\Python37-32\lib\site-packages\nornir\core\task.py", line 62, in start
    r = self.task(self, **self.params)
  File "C:\Users\m_buck\AppData\Local\Programs\Python\Python37-32\lib\site-packages\nornir\plugins\tasks\networking\netmiko_send_command.py", line 26, in netmiko_send_command
    net_connect = task.host.get_connection("netmiko", task.nornir.config)
  File "C:\Users\m_buck\AppData\Local\Programs\Python\Python37-32\lib\site-packages\nornir\core\inventory.py", line 297, in get_connection
    **self.get_connection_parameters(connection).dict(),
  File "C:\Users\m_buck\AppData\Local\Programs\Python\Python37-32\lib\site-packages\nornir\core\inventory.py", line 347, in open_connection
    configuration=configuration,
  File "C:\Users\m_buck\AppData\Local\Programs\Python\Python37-32\lib\site-packages\nornir\plugins\connections\netmiko.py", line 51, in open
    self.connection = ConnectHandler(**parameters)
  File "C:\Users\m_buck\AppData\Local\Programs\Python\Python37-32\lib\site-packages\netmiko\ssh_dispatcher.py", line 214, in ConnectHandler
    if kwargs['device_type'] not in platforms:
KeyError: 'device_type'

2019-03-06 09:47:31,126 - nornir.core.task -    ERROR -      start() - GNS.CE1: Traceback (most recent call last):
  File "C:\Users\m_buck\AppData\Local\Programs\Python\Python37-32\lib\site-packages\nornir\core\task.py", line 62, in start
    r = self.task(self, **self.params)
  File "C:\Users\m_buck\AppData\Local\Programs\Python\Python37-32\lib\site-packages\nornir\plugins\tasks\networking\netmiko_send_command.py", line 26, in netmiko_send_command
    net_connect = task.host.get_connection("netmiko", task.nornir.config)
  File "C:\Users\m_buck\AppData\Local\Programs\Python\Python37-32\lib\site-packages\nornir\core\inventory.py", line 297, in get_connection
    **self.get_connection_parameters(connection).dict(),
  File "C:\Users\m_buck\AppData\Local\Programs\Python\Python37-32\lib\site-packages\nornir\core\inventory.py", line 347, in open_connection
    configuration=configuration,
  File "C:\Users\m_buck\AppData\Local\Programs\Python\Python37-32\lib\site-packages\nornir\plugins\connections\netmiko.py", line 51, in open
    self.connection = ConnectHandler(**parameters)
  File "C:\Users\m_buck\AppData\Local\Programs\Python\Python37-32\lib\site-packages\netmiko\ssh_dispatcher.py", line 214, in ConnectHandler
    if kwargs['device_type'] not in platforms:
KeyError: 'device_type'

2019-03-06 09:47:31,182 -  nornir.core -     INFO -        run() - Running task 'netmiko_send_command' with num_workers: 100
2019-03-06 09:47:31,182 -  nornir.core -     INFO -        run() - Running task 'netmiko_send_command' with num_workers: 100
2019-03-06 09:47:31,182 -  nornir.core -    DEBUG -        run() - {'command_string': 'sh log'}
2019-03-06 09:47:31,182 -  nornir.core -    DEBUG -        run() - {'command_string': 'sh log'}
2019-03-06 09:47:31,304 -  nornir.core -     INFO -        run() - Running task 'netmiko_send_command' with num_workers: 100
2019-03-06 09:47:31,304 -  nornir.core -     INFO -        run() - Running task 'netmiko_send_command' with num_workers: 100
2019-03-06 09:47:31,304 -  nornir.core -    DEBUG -        run() - {'command_string': 'sh run | i CRC'}
2019-03-06 09:47:31,304 -  nornir.core -    DEBUG -        run() - {'command_string': 'sh run | i CRC'}
2019-05-09 16:15:23,598 -  nornir.core -     INFO -        run() - Running task 'netmiko_send_command' with num_workers: 100
2019-05-09 16:15:23,598 -  nornir.core -     INFO -        run() - Running task 'netmiko_send_command' with num_workers: 100
2019-05-09 16:15:23,599 -  nornir.core -    DEBUG -        run() - {'command_string': 'sh int status'}
2019-05-09 16:15:23,599 -  nornir.core -    DEBUG -        run() - {'command_string': 'sh int status'}
2019-05-09 16:15:23,647 - nornir.core.task -     INFO -      start() - NET002A-101HSMANCHESTER.CE1: netmiko_send_command: running task
2019-05-09 16:15:23,647 - nornir.core.task -     INFO -      start() - NET002A-101HSMANCHESTER.CE1: netmiko_send_command: running task
2019-05-09 16:15:44,702 - nornir.core.task -    ERROR -      start() - NET002A-101HSMANCHESTER.CE1: Traceback (most recent call last):
  File "C:\Users\m_buck\AppData\Local\Programs\Python\Python37-32\lib\site-packages\netmiko\base_connection.py", line 782, in establish_connection
    self.remote_conn_pre.connect(**ssh_connect_params)
  File "C:\Users\m_buck\AppData\Local\Programs\Python\Python37-32\lib\site-packages\paramiko\client.py", line 343, in connect
    retry_on_signal(lambda: sock.connect(addr))
  File "C:\Users\m_buck\AppData\Local\Programs\Python\Python37-32\lib\site-packages\paramiko\util.py", line 280, in retry_on_signal
    return function()
  File "C:\Users\m_buck\AppData\Local\Programs\Python\Python37-32\lib\site-packages\paramiko\client.py", line 343, in <lambda>
    retry_on_signal(lambda: sock.connect(addr))
TimeoutError: [WinError 10060] A connection attempt failed because the connected party did not properly respond after a period of time, or established connection failed because connected host has failed to respond

During handling of the above exception, another exception occurred:

Traceback (most recent call last):
  File "C:\Users\m_buck\AppData\Local\Programs\Python\Python37-32\lib\site-packages\nornir\core\task.py", line 62, in start
    r = self.task(self, **self.params)
  File "C:\Users\m_buck\AppData\Local\Programs\Python\Python37-32\lib\site-packages\nornir\plugins\tasks\networking\netmiko_send_command.py", line 26, in netmiko_send_command
    net_connect = task.host.get_connection("netmiko", task.nornir.config)
  File "C:\Users\m_buck\AppData\Local\Programs\Python\Python37-32\lib\site-packages\nornir\core\inventory.py", line 297, in get_connection
    **self.get_connection_parameters(connection).dict(),
  File "C:\Users\m_buck\AppData\Local\Programs\Python\Python37-32\lib\site-packages\nornir\core\inventory.py", line 347, in open_connection
    configuration=configuration,
  File "C:\Users\m_buck\AppData\Local\Programs\Python\Python37-32\lib\site-packages\nornir\plugins\connections\netmiko.py", line 51, in open
    self.connection = ConnectHandler(**parameters)
  File "C:\Users\m_buck\AppData\Local\Programs\Python\Python37-32\lib\site-packages\netmiko\ssh_dispatcher.py", line 218, in ConnectHandler
    return ConnectionClass(*args, **kwargs)
  File "C:\Users\m_buck\AppData\Local\Programs\Python\Python37-32\lib\site-packages\netmiko\base_connection.py", line 270, in __init__
    self.establish_connection()
  File "C:\Users\m_buck\AppData\Local\Programs\Python\Python37-32\lib\site-packages\netmiko\base_connection.py", line 787, in establish_connection
    raise NetMikoTimeoutException(msg)
netmiko.ssh_exception.NetMikoTimeoutException: Connection to device timed-out: cisco_ios 10.161.37.212:22

2019-05-09 16:15:44,702 - nornir.core.task -    ERROR -      start() - NET002A-101HSMANCHESTER.CE1: Traceback (most recent call last):
  File "C:\Users\m_buck\AppData\Local\Programs\Python\Python37-32\lib\site-packages\netmiko\base_connection.py", line 782, in establish_connection
    self.remote_conn_pre.connect(**ssh_connect_params)
  File "C:\Users\m_buck\AppData\Local\Programs\Python\Python37-32\lib\site-packages\paramiko\client.py", line 343, in connect
    retry_on_signal(lambda: sock.connect(addr))
  File "C:\Users\m_buck\AppData\Local\Programs\Python\Python37-32\lib\site-packages\paramiko\util.py", line 280, in retry_on_signal
    return function()
  File "C:\Users\m_buck\AppData\Local\Programs\Python\Python37-32\lib\site-packages\paramiko\client.py", line 343, in <lambda>
    retry_on_signal(lambda: sock.connect(addr))
TimeoutError: [WinError 10060] A connection attempt failed because the connected party did not properly respond after a period of time, or established connection failed because connected host has failed to respond

During handling of the above exception, another exception occurred:

Traceback (most recent call last):
  File "C:\Users\m_buck\AppData\Local\Programs\Python\Python37-32\lib\site-packages\nornir\core\task.py", line 62, in start
    r = self.task(self, **self.params)
  File "C:\Users\m_buck\AppData\Local\Programs\Python\Python37-32\lib\site-packages\nornir\plugins\tasks\networking\netmiko_send_command.py", line 26, in netmiko_send_command
    net_connect = task.host.get_connection("netmiko", task.nornir.config)
  File "C:\Users\m_buck\AppData\Local\Programs\Python\Python37-32\lib\site-packages\nornir\core\inventory.py", line 297, in get_connection
    **self.get_connection_parameters(connection).dict(),
  File "C:\Users\m_buck\AppData\Local\Programs\Python\Python37-32\lib\site-packages\nornir\core\inventory.py", line 347, in open_connection
    configuration=configuration,
  File "C:\Users\m_buck\AppData\Local\Programs\Python\Python37-32\lib\site-packages\nornir\plugins\connections\netmiko.py", line 51, in open
    self.connection = ConnectHandler(**parameters)
  File "C:\Users\m_buck\AppData\Local\Programs\Python\Python37-32\lib\site-packages\netmiko\ssh_dispatcher.py", line 218, in ConnectHandler
    return ConnectionClass(*args, **kwargs)
  File "C:\Users\m_buck\AppData\Local\Programs\Python\Python37-32\lib\site-packages\netmiko\base_connection.py", line 270, in __init__
    self.establish_connection()
  File "C:\Users\m_buck\AppData\Local\Programs\Python\Python37-32\lib\site-packages\netmiko\base_connection.py", line 787, in establish_connection
    raise NetMikoTimeoutException(msg)
netmiko.ssh_exception.NetMikoTimeoutException: Connection to device timed-out: cisco_ios 10.161.37.212:22

2019-05-13 11:34:24,641 -  nornir.core -     INFO -        run() - Running task 'netmiko_send_command' with num_workers: 100
2019-05-13 11:34:24,641 -  nornir.core -     INFO -        run() - Running task 'netmiko_send_command' with num_workers: 100
2019-05-13 11:34:24,642 -  nornir.core -    DEBUG -        run() - {'command_string': 'sh int status'}
2019-05-13 11:34:24,642 -  nornir.core -    DEBUG -        run() - {'command_string': 'sh int status'}
2019-05-13 11:34:24,697 - nornir.core.task -     INFO -      start() - NET002A-101HSMANCHESTER.CE1: netmiko_send_command: running task
2019-05-13 11:34:24,697 - nornir.core.task -     INFO -      start() - NET002A-101HSMANCHESTER.CE1: netmiko_send_command: running task
2019-05-13 11:34:45,815 - nornir.core.task -    ERROR -      start() - NET002A-101HSMANCHESTER.CE1: Traceback (most recent call last):
  File "C:\Users\m_buck\AppData\Local\Programs\Python\Python37-32\lib\site-packages\netmiko\base_connection.py", line 782, in establish_connection
    self.remote_conn_pre.connect(**ssh_connect_params)
  File "C:\Users\m_buck\AppData\Local\Programs\Python\Python37-32\lib\site-packages\paramiko\client.py", line 343, in connect
    retry_on_signal(lambda: sock.connect(addr))
  File "C:\Users\m_buck\AppData\Local\Programs\Python\Python37-32\lib\site-packages\paramiko\util.py", line 280, in retry_on_signal
    return function()
  File "C:\Users\m_buck\AppData\Local\Programs\Python\Python37-32\lib\site-packages\paramiko\client.py", line 343, in <lambda>
    retry_on_signal(lambda: sock.connect(addr))
TimeoutError: [WinError 10060] A connection attempt failed because the connected party did not properly respond after a period of time, or established connection failed because connected host has failed to respond

During handling of the above exception, another exception occurred:

Traceback (most recent call last):
  File "C:\Users\m_buck\AppData\Local\Programs\Python\Python37-32\lib\site-packages\nornir\core\task.py", line 62, in start
    r = self.task(self, **self.params)
  File "C:\Users\m_buck\AppData\Local\Programs\Python\Python37-32\lib\site-packages\nornir\plugins\tasks\networking\netmiko_send_command.py", line 26, in netmiko_send_command
    net_connect = task.host.get_connection("netmiko", task.nornir.config)
  File "C:\Users\m_buck\AppData\Local\Programs\Python\Python37-32\lib\site-packages\nornir\core\inventory.py", line 297, in get_connection
    **self.get_connection_parameters(connection).dict(),
  File "C:\Users\m_buck\AppData\Local\Programs\Python\Python37-32\lib\site-packages\nornir\core\inventory.py", line 347, in open_connection
    configuration=configuration,
  File "C:\Users\m_buck\AppData\Local\Programs\Python\Python37-32\lib\site-packages\nornir\plugins\connections\netmiko.py", line 51, in open
    self.connection = ConnectHandler(**parameters)
  File "C:\Users\m_buck\AppData\Local\Programs\Python\Python37-32\lib\site-packages\netmiko\ssh_dispatcher.py", line 218, in ConnectHandler
    return ConnectionClass(*args, **kwargs)
  File "C:\Users\m_buck\AppData\Local\Programs\Python\Python37-32\lib\site-packages\netmiko\base_connection.py", line 270, in __init__
    self.establish_connection()
  File "C:\Users\m_buck\AppData\Local\Programs\Python\Python37-32\lib\site-packages\netmiko\base_connection.py", line 787, in establish_connection
    raise NetMikoTimeoutException(msg)
netmiko.ssh_exception.NetMikoTimeoutException: Connection to device timed-out: cisco_ios 10.161.37.212:22

2019-05-13 11:34:45,815 - nornir.core.task -    ERROR -      start() - NET002A-101HSMANCHESTER.CE1: Traceback (most recent call last):
  File "C:\Users\m_buck\AppData\Local\Programs\Python\Python37-32\lib\site-packages\netmiko\base_connection.py", line 782, in establish_connection
    self.remote_conn_pre.connect(**ssh_connect_params)
  File "C:\Users\m_buck\AppData\Local\Programs\Python\Python37-32\lib\site-packages\paramiko\client.py", line 343, in connect
    retry_on_signal(lambda: sock.connect(addr))
  File "C:\Users\m_buck\AppData\Local\Programs\Python\Python37-32\lib\site-packages\paramiko\util.py", line 280, in retry_on_signal
    return function()
  File "C:\Users\m_buck\AppData\Local\Programs\Python\Python37-32\lib\site-packages\paramiko\client.py", line 343, in <lambda>
    retry_on_signal(lambda: sock.connect(addr))
TimeoutError: [WinError 10060] A connection attempt failed because the connected party did not properly respond after a period of time, or established connection failed because connected host has failed to respond

During handling of the above exception, another exception occurred:

Traceback (most recent call last):
  File "C:\Users\m_buck\AppData\Local\Programs\Python\Python37-32\lib\site-packages\nornir\core\task.py", line 62, in start
    r = self.task(self, **self.params)
  File "C:\Users\m_buck\AppData\Local\Programs\Python\Python37-32\lib\site-packages\nornir\plugins\tasks\networking\netmiko_send_command.py", line 26, in netmiko_send_command
    net_connect = task.host.get_connection("netmiko", task.nornir.config)
  File "C:\Users\m_buck\AppData\Local\Programs\Python\Python37-32\lib\site-packages\nornir\core\inventory.py", line 297, in get_connection
    **self.get_connection_parameters(connection).dict(),
  File "C:\Users\m_buck\AppData\Local\Programs\Python\Python37-32\lib\site-packages\nornir\core\inventory.py", line 347, in open_connection
    configuration=configuration,
  File "C:\Users\m_buck\AppData\Local\Programs\Python\Python37-32\lib\site-packages\nornir\plugins\connections\netmiko.py", line 51, in open
    self.connection = ConnectHandler(**parameters)
  File "C:\Users\m_buck\AppData\Local\Programs\Python\Python37-32\lib\site-packages\netmiko\ssh_dispatcher.py", line 218, in ConnectHandler
    return ConnectionClass(*args, **kwargs)
  File "C:\Users\m_buck\AppData\Local\Programs\Python\Python37-32\lib\site-packages\netmiko\base_connection.py", line 270, in __init__
    self.establish_connection()
  File "C:\Users\m_buck\AppData\Local\Programs\Python\Python37-32\lib\site-packages\netmiko\base_connection.py", line 787, in establish_connection
    raise NetMikoTimeoutException(msg)
netmiko.ssh_exception.NetMikoTimeoutException: Connection to device timed-out: cisco_ios 10.161.37.212:22

2019-05-13 11:41:50,097 -  nornir.core -     INFO -        run() - Running task 'netmiko_send_command' with num_workers: 100
2019-05-13 11:41:50,097 -  nornir.core -     INFO -        run() - Running task 'netmiko_send_command' with num_workers: 100
2019-05-13 11:41:50,097 -  nornir.core -    DEBUG -        run() - {'command_string': 'sh int status'}
2019-05-13 11:41:50,097 -  nornir.core -    DEBUG -        run() - {'command_string': 'sh int status'}
2019-05-13 11:41:50,224 - nornir.core.task -     INFO -      start() - NET002A-101HSMANCHESTER.CE1: netmiko_send_command: running task
2019-05-13 11:41:50,224 - nornir.core.task -     INFO -      start() - NET002A-101HSMANCHESTER.CE1: netmiko_send_command: running task
2019-05-13 11:42:11,241 - nornir.core.task -    ERROR -      start() - NET002A-101HSMANCHESTER.CE1: Traceback (most recent call last):
  File "C:\Users\m_buck\AppData\Local\Programs\Python\Python37-32\lib\site-packages\netmiko\base_connection.py", line 782, in establish_connection
    self.remote_conn_pre.connect(**ssh_connect_params)
  File "C:\Users\m_buck\AppData\Local\Programs\Python\Python37-32\lib\site-packages\paramiko\client.py", line 343, in connect
    retry_on_signal(lambda: sock.connect(addr))
  File "C:\Users\m_buck\AppData\Local\Programs\Python\Python37-32\lib\site-packages\paramiko\util.py", line 280, in retry_on_signal
    return function()
  File "C:\Users\m_buck\AppData\Local\Programs\Python\Python37-32\lib\site-packages\paramiko\client.py", line 343, in <lambda>
    retry_on_signal(lambda: sock.connect(addr))
TimeoutError: [WinError 10060] A connection attempt failed because the connected party did not properly respond after a period of time, or established connection failed because connected host has failed to respond

During handling of the above exception, another exception occurred:

Traceback (most recent call last):
  File "C:\Users\m_buck\AppData\Local\Programs\Python\Python37-32\lib\site-packages\nornir\core\task.py", line 62, in start
    r = self.task(self, **self.params)
  File "C:\Users\m_buck\AppData\Local\Programs\Python\Python37-32\lib\site-packages\nornir\plugins\tasks\networking\netmiko_send_command.py", line 26, in netmiko_send_command
    net_connect = task.host.get_connection("netmiko", task.nornir.config)
  File "C:\Users\m_buck\AppData\Local\Programs\Python\Python37-32\lib\site-packages\nornir\core\inventory.py", line 297, in get_connection
    **self.get_connection_parameters(connection).dict(),
  File "C:\Users\m_buck\AppData\Local\Programs\Python\Python37-32\lib\site-packages\nornir\core\inventory.py", line 347, in open_connection
    configuration=configuration,
  File "C:\Users\m_buck\AppData\Local\Programs\Python\Python37-32\lib\site-packages\nornir\plugins\connections\netmiko.py", line 51, in open
    self.connection = ConnectHandler(**parameters)
  File "C:\Users\m_buck\AppData\Local\Programs\Python\Python37-32\lib\site-packages\netmiko\ssh_dispatcher.py", line 218, in ConnectHandler
    return ConnectionClass(*args, **kwargs)
  File "C:\Users\m_buck\AppData\Local\Programs\Python\Python37-32\lib\site-packages\netmiko\base_connection.py", line 270, in __init__
    self.establish_connection()
  File "C:\Users\m_buck\AppData\Local\Programs\Python\Python37-32\lib\site-packages\netmiko\base_connection.py", line 787, in establish_connection
    raise NetMikoTimeoutException(msg)
netmiko.ssh_exception.NetMikoTimeoutException: Connection to device timed-out: cisco_ios 10.161.37.212:22

2019-05-13 11:42:11,241 - nornir.core.task -    ERROR -      start() - NET002A-101HSMANCHESTER.CE1: Traceback (most recent call last):
  File "C:\Users\m_buck\AppData\Local\Programs\Python\Python37-32\lib\site-packages\netmiko\base_connection.py", line 782, in establish_connection
    self.remote_conn_pre.connect(**ssh_connect_params)
  File "C:\Users\m_buck\AppData\Local\Programs\Python\Python37-32\lib\site-packages\paramiko\client.py", line 343, in connect
    retry_on_signal(lambda: sock.connect(addr))
  File "C:\Users\m_buck\AppData\Local\Programs\Python\Python37-32\lib\site-packages\paramiko\util.py", line 280, in retry_on_signal
    return function()
  File "C:\Users\m_buck\AppData\Local\Programs\Python\Python37-32\lib\site-packages\paramiko\client.py", line 343, in <lambda>
    retry_on_signal(lambda: sock.connect(addr))
TimeoutError: [WinError 10060] A connection attempt failed because the connected party did not properly respond after a period of time, or established connection failed because connected host has failed to respond

During handling of the above exception, another exception occurred:

Traceback (most recent call last):
  File "C:\Users\m_buck\AppData\Local\Programs\Python\Python37-32\lib\site-packages\nornir\core\task.py", line 62, in start
    r = self.task(self, **self.params)
  File "C:\Users\m_buck\AppData\Local\Programs\Python\Python37-32\lib\site-packages\nornir\plugins\tasks\networking\netmiko_send_command.py", line 26, in netmiko_send_command
    net_connect = task.host.get_connection("netmiko", task.nornir.config)
  File "C:\Users\m_buck\AppData\Local\Programs\Python\Python37-32\lib\site-packages\nornir\core\inventory.py", line 297, in get_connection
    **self.get_connection_parameters(connection).dict(),
  File "C:\Users\m_buck\AppData\Local\Programs\Python\Python37-32\lib\site-packages\nornir\core\inventory.py", line 347, in open_connection
    configuration=configuration,
  File "C:\Users\m_buck\AppData\Local\Programs\Python\Python37-32\lib\site-packages\nornir\plugins\connections\netmiko.py", line 51, in open
    self.connection = ConnectHandler(**parameters)
  File "C:\Users\m_buck\AppData\Local\Programs\Python\Python37-32\lib\site-packages\netmiko\ssh_dispatcher.py", line 218, in ConnectHandler
    return ConnectionClass(*args, **kwargs)
  File "C:\Users\m_buck\AppData\Local\Programs\Python\Python37-32\lib\site-packages\netmiko\base_connection.py", line 270, in __init__
    self.establish_connection()
  File "C:\Users\m_buck\AppData\Local\Programs\Python\Python37-32\lib\site-packages\netmiko\base_connection.py", line 787, in establish_connection
    raise NetMikoTimeoutException(msg)
netmiko.ssh_exception.NetMikoTimeoutException: Connection to device timed-out: cisco_ios 10.161.37.212:22

2019-05-15 14:35:03,260 -  nornir.core -     INFO -        run() - Running task 'netmiko_send_command' with num_workers: 100
2019-05-15 14:35:03,260 -  nornir.core -     INFO -        run() - Running task 'netmiko_send_command' with num_workers: 100
2019-05-15 14:35:03,261 -  nornir.core -    DEBUG -        run() - {'command_string': 'sh int status'}
2019-05-15 14:35:03,261 -  nornir.core -    DEBUG -        run() - {'command_string': 'sh int status'}
2019-05-15 14:35:03,319 - nornir.core.task -     INFO -      start() - NET002A-101HSMANCHESTER.CE1: netmiko_send_command: running task
2019-05-15 14:35:03,319 - nornir.core.task -     INFO -      start() - NET002A-101HSMANCHESTER.CE1: netmiko_send_command: running task
2019-05-15 14:35:24,325 - nornir.core.task -    ERROR -      start() - NET002A-101HSMANCHESTER.CE1: Traceback (most recent call last):
  File "C:\Users\m_buck\AppData\Local\Programs\Python\Python37-32\lib\site-packages\netmiko\base_connection.py", line 782, in establish_connection
    self.remote_conn_pre.connect(**ssh_connect_params)
  File "C:\Users\m_buck\AppData\Local\Programs\Python\Python37-32\lib\site-packages\paramiko\client.py", line 343, in connect
    retry_on_signal(lambda: sock.connect(addr))
  File "C:\Users\m_buck\AppData\Local\Programs\Python\Python37-32\lib\site-packages\paramiko\util.py", line 280, in retry_on_signal
    return function()
  File "C:\Users\m_buck\AppData\Local\Programs\Python\Python37-32\lib\site-packages\paramiko\client.py", line 343, in <lambda>
    retry_on_signal(lambda: sock.connect(addr))
TimeoutError: [WinError 10060] A connection attempt failed because the connected party did not properly respond after a period of time, or established connection failed because connected host has failed to respond

During handling of the above exception, another exception occurred:

Traceback (most recent call last):
  File "C:\Users\m_buck\AppData\Local\Programs\Python\Python37-32\lib\site-packages\nornir\core\task.py", line 62, in start
    r = self.task(self, **self.params)
  File "C:\Users\m_buck\AppData\Local\Programs\Python\Python37-32\lib\site-packages\nornir\plugins\tasks\networking\netmiko_send_command.py", line 26, in netmiko_send_command
    net_connect = task.host.get_connection("netmiko", task.nornir.config)
  File "C:\Users\m_buck\AppData\Local\Programs\Python\Python37-32\lib\site-packages\nornir\core\inventory.py", line 297, in get_connection
    **self.get_connection_parameters(connection).dict(),
  File "C:\Users\m_buck\AppData\Local\Programs\Python\Python37-32\lib\site-packages\nornir\core\inventory.py", line 347, in open_connection
    configuration=configuration,
  File "C:\Users\m_buck\AppData\Local\Programs\Python\Python37-32\lib\site-packages\nornir\plugins\connections\netmiko.py", line 51, in open
    self.connection = ConnectHandler(**parameters)
  File "C:\Users\m_buck\AppData\Local\Programs\Python\Python37-32\lib\site-packages\netmiko\ssh_dispatcher.py", line 218, in ConnectHandler
    return ConnectionClass(*args, **kwargs)
  File "C:\Users\m_buck\AppData\Local\Programs\Python\Python37-32\lib\site-packages\netmiko\base_connection.py", line 270, in __init__
    self.establish_connection()
  File "C:\Users\m_buck\AppData\Local\Programs\Python\Python37-32\lib\site-packages\netmiko\base_connection.py", line 787, in establish_connection
    raise NetMikoTimeoutException(msg)
netmiko.ssh_exception.NetMikoTimeoutException: Connection to device timed-out: cisco_ios 10.161.37.212:22

2019-05-15 14:35:24,325 - nornir.core.task -    ERROR -      start() - NET002A-101HSMANCHESTER.CE1: Traceback (most recent call last):
  File "C:\Users\m_buck\AppData\Local\Programs\Python\Python37-32\lib\site-packages\netmiko\base_connection.py", line 782, in establish_connection
    self.remote_conn_pre.connect(**ssh_connect_params)
  File "C:\Users\m_buck\AppData\Local\Programs\Python\Python37-32\lib\site-packages\paramiko\client.py", line 343, in connect
    retry_on_signal(lambda: sock.connect(addr))
  File "C:\Users\m_buck\AppData\Local\Programs\Python\Python37-32\lib\site-packages\paramiko\util.py", line 280, in retry_on_signal
    return function()
  File "C:\Users\m_buck\AppData\Local\Programs\Python\Python37-32\lib\site-packages\paramiko\client.py", line 343, in <lambda>
    retry_on_signal(lambda: sock.connect(addr))
TimeoutError: [WinError 10060] A connection attempt failed because the connected party did not properly respond after a period of time, or established connection failed because connected host has failed to respond

During handling of the above exception, another exception occurred:

Traceback (most recent call last):
  File "C:\Users\m_buck\AppData\Local\Programs\Python\Python37-32\lib\site-packages\nornir\core\task.py", line 62, in start
    r = self.task(self, **self.params)
  File "C:\Users\m_buck\AppData\Local\Programs\Python\Python37-32\lib\site-packages\nornir\plugins\tasks\networking\netmiko_send_command.py", line 26, in netmiko_send_command
    net_connect = task.host.get_connection("netmiko", task.nornir.config)
  File "C:\Users\m_buck\AppData\Local\Programs\Python\Python37-32\lib\site-packages\nornir\core\inventory.py", line 297, in get_connection
    **self.get_connection_parameters(connection).dict(),
  File "C:\Users\m_buck\AppData\Local\Programs\Python\Python37-32\lib\site-packages\nornir\core\inventory.py", line 347, in open_connection
    configuration=configuration,
  File "C:\Users\m_buck\AppData\Local\Programs\Python\Python37-32\lib\site-packages\nornir\plugins\connections\netmiko.py", line 51, in open
    self.connection = ConnectHandler(**parameters)
  File "C:\Users\m_buck\AppData\Local\Programs\Python\Python37-32\lib\site-packages\netmiko\ssh_dispatcher.py", line 218, in ConnectHandler
    return ConnectionClass(*args, **kwargs)
  File "C:\Users\m_buck\AppData\Local\Programs\Python\Python37-32\lib\site-packages\netmiko\base_connection.py", line 270, in __init__
    self.establish_connection()
  File "C:\Users\m_buck\AppData\Local\Programs\Python\Python37-32\lib\site-packages\netmiko\base_connection.py", line 787, in establish_connection
    raise NetMikoTimeoutException(msg)
netmiko.ssh_exception.NetMikoTimeoutException: Connection to device timed-out: cisco_ios 10.161.37.212:22

2019-05-15 14:39:15,700 -  nornir.core -     INFO -        run() - Running task 'netmiko_send_command' with num_workers: 100
2019-05-15 14:39:15,700 -  nornir.core -     INFO -        run() - Running task 'netmiko_send_command' with num_workers: 100
2019-05-15 14:39:15,700 -  nornir.core -    DEBUG -        run() - {'command_string': 'sh int status'}
2019-05-15 14:39:15,700 -  nornir.core -    DEBUG -        run() - {'command_string': 'sh int status'}
2019-05-15 14:39:15,737 - nornir.core.task -     INFO -      start() - NET002A-101HSMANCHESTER.CE1: netmiko_send_command: running task
2019-05-15 14:39:15,737 - nornir.core.task -     INFO -      start() - NET14070-DSL-TONBRIDGE.CE1: netmiko_send_command: running task
2019-05-15 14:39:15,737 - nornir.core.task -     INFO -      start() - NET002A-101HSMANCHESTER.CE1: netmiko_send_command: running task
2019-05-15 14:39:15,737 - nornir.core.task -     INFO -      start() - NET14070-DSL-TONBRIDGE.CE1: netmiko_send_command: running task
2019-05-15 14:39:36,746 - nornir.core.task -    ERROR -      start() - NET002A-101HSMANCHESTER.CE1: Traceback (most recent call last):
  File "C:\Users\m_buck\AppData\Local\Programs\Python\Python37-32\lib\site-packages\netmiko\base_connection.py", line 782, in establish_connection
    self.remote_conn_pre.connect(**ssh_connect_params)
  File "C:\Users\m_buck\AppData\Local\Programs\Python\Python37-32\lib\site-packages\paramiko\client.py", line 343, in connect
    retry_on_signal(lambda: sock.connect(addr))
  File "C:\Users\m_buck\AppData\Local\Programs\Python\Python37-32\lib\site-packages\paramiko\util.py", line 280, in retry_on_signal
    return function()
  File "C:\Users\m_buck\AppData\Local\Programs\Python\Python37-32\lib\site-packages\paramiko\client.py", line 343, in <lambda>
    retry_on_signal(lambda: sock.connect(addr))
TimeoutError: [WinError 10060] A connection attempt failed because the connected party did not properly respond after a period of time, or established connection failed because connected host has failed to respond

During handling of the above exception, another exception occurred:

Traceback (most recent call last):
  File "C:\Users\m_buck\AppData\Local\Programs\Python\Python37-32\lib\site-packages\nornir\core\task.py", line 62, in start
    r = self.task(self, **self.params)
  File "C:\Users\m_buck\AppData\Local\Programs\Python\Python37-32\lib\site-packages\nornir\plugins\tasks\networking\netmiko_send_command.py", line 26, in netmiko_send_command
    net_connect = task.host.get_connection("netmiko", task.nornir.config)
  File "C:\Users\m_buck\AppData\Local\Programs\Python\Python37-32\lib\site-packages\nornir\core\inventory.py", line 297, in get_connection
    **self.get_connection_parameters(connection).dict(),
  File "C:\Users\m_buck\AppData\Local\Programs\Python\Python37-32\lib\site-packages\nornir\core\inventory.py", line 347, in open_connection
    configuration=configuration,
  File "C:\Users\m_buck\AppData\Local\Programs\Python\Python37-32\lib\site-packages\nornir\plugins\connections\netmiko.py", line 51, in open
    self.connection = ConnectHandler(**parameters)
  File "C:\Users\m_buck\AppData\Local\Programs\Python\Python37-32\lib\site-packages\netmiko\ssh_dispatcher.py", line 218, in ConnectHandler
    return ConnectionClass(*args, **kwargs)
  File "C:\Users\m_buck\AppData\Local\Programs\Python\Python37-32\lib\site-packages\netmiko\base_connection.py", line 270, in __init__
    self.establish_connection()
  File "C:\Users\m_buck\AppData\Local\Programs\Python\Python37-32\lib\site-packages\netmiko\base_connection.py", line 787, in establish_connection
    raise NetMikoTimeoutException(msg)
netmiko.ssh_exception.NetMikoTimeoutException: Connection to device timed-out: cisco_ios 10.161.37.212:22

2019-05-15 14:39:36,746 - nornir.core.task -    ERROR -      start() - NET002A-101HSMANCHESTER.CE1: Traceback (most recent call last):
  File "C:\Users\m_buck\AppData\Local\Programs\Python\Python37-32\lib\site-packages\netmiko\base_connection.py", line 782, in establish_connection
    self.remote_conn_pre.connect(**ssh_connect_params)
  File "C:\Users\m_buck\AppData\Local\Programs\Python\Python37-32\lib\site-packages\paramiko\client.py", line 343, in connect
    retry_on_signal(lambda: sock.connect(addr))
  File "C:\Users\m_buck\AppData\Local\Programs\Python\Python37-32\lib\site-packages\paramiko\util.py", line 280, in retry_on_signal
    return function()
  File "C:\Users\m_buck\AppData\Local\Programs\Python\Python37-32\lib\site-packages\paramiko\client.py", line 343, in <lambda>
    retry_on_signal(lambda: sock.connect(addr))
TimeoutError: [WinError 10060] A connection attempt failed because the connected party did not properly respond after a period of time, or established connection failed because connected host has failed to respond

During handling of the above exception, another exception occurred:

Traceback (most recent call last):
  File "C:\Users\m_buck\AppData\Local\Programs\Python\Python37-32\lib\site-packages\nornir\core\task.py", line 62, in start
    r = self.task(self, **self.params)
  File "C:\Users\m_buck\AppData\Local\Programs\Python\Python37-32\lib\site-packages\nornir\plugins\tasks\networking\netmiko_send_command.py", line 26, in netmiko_send_command
    net_connect = task.host.get_connection("netmiko", task.nornir.config)
  File "C:\Users\m_buck\AppData\Local\Programs\Python\Python37-32\lib\site-packages\nornir\core\inventory.py", line 297, in get_connection
    **self.get_connection_parameters(connection).dict(),
  File "C:\Users\m_buck\AppData\Local\Programs\Python\Python37-32\lib\site-packages\nornir\core\inventory.py", line 347, in open_connection
    configuration=configuration,
  File "C:\Users\m_buck\AppData\Local\Programs\Python\Python37-32\lib\site-packages\nornir\plugins\connections\netmiko.py", line 51, in open
    self.connection = ConnectHandler(**parameters)
  File "C:\Users\m_buck\AppData\Local\Programs\Python\Python37-32\lib\site-packages\netmiko\ssh_dispatcher.py", line 218, in ConnectHandler
    return ConnectionClass(*args, **kwargs)
  File "C:\Users\m_buck\AppData\Local\Programs\Python\Python37-32\lib\site-packages\netmiko\base_connection.py", line 270, in __init__
    self.establish_connection()
  File "C:\Users\m_buck\AppData\Local\Programs\Python\Python37-32\lib\site-packages\netmiko\base_connection.py", line 787, in establish_connection
    raise NetMikoTimeoutException(msg)
netmiko.ssh_exception.NetMikoTimeoutException: Connection to device timed-out: cisco_ios 10.161.37.212:22

2019-05-15 14:39:36,747 - nornir.core.task -    ERROR -      start() - NET14070-DSL-TONBRIDGE.CE1: Traceback (most recent call last):
  File "C:\Users\m_buck\AppData\Local\Programs\Python\Python37-32\lib\site-packages\netmiko\base_connection.py", line 782, in establish_connection
    self.remote_conn_pre.connect(**ssh_connect_params)
  File "C:\Users\m_buck\AppData\Local\Programs\Python\Python37-32\lib\site-packages\paramiko\client.py", line 343, in connect
    retry_on_signal(lambda: sock.connect(addr))
  File "C:\Users\m_buck\AppData\Local\Programs\Python\Python37-32\lib\site-packages\paramiko\util.py", line 280, in retry_on_signal
    return function()
  File "C:\Users\m_buck\AppData\Local\Programs\Python\Python37-32\lib\site-packages\paramiko\client.py", line 343, in <lambda>
    retry_on_signal(lambda: sock.connect(addr))
TimeoutError: [WinError 10060] A connection attempt failed because the connected party did not properly respond after a period of time, or established connection failed because connected host has failed to respond

During handling of the above exception, another exception occurred:

Traceback (most recent call last):
  File "C:\Users\m_buck\AppData\Local\Programs\Python\Python37-32\lib\site-packages\nornir\core\task.py", line 62, in start
    r = self.task(self, **self.params)
  File "C:\Users\m_buck\AppData\Local\Programs\Python\Python37-32\lib\site-packages\nornir\plugins\tasks\networking\netmiko_send_command.py", line 26, in netmiko_send_command
    net_connect = task.host.get_connection("netmiko", task.nornir.config)
  File "C:\Users\m_buck\AppData\Local\Programs\Python\Python37-32\lib\site-packages\nornir\core\inventory.py", line 297, in get_connection
    **self.get_connection_parameters(connection).dict(),
  File "C:\Users\m_buck\AppData\Local\Programs\Python\Python37-32\lib\site-packages\nornir\core\inventory.py", line 347, in open_connection
    configuration=configuration,
  File "C:\Users\m_buck\AppData\Local\Programs\Python\Python37-32\lib\site-packages\nornir\plugins\connections\netmiko.py", line 51, in open
    self.connection = ConnectHandler(**parameters)
  File "C:\Users\m_buck\AppData\Local\Programs\Python\Python37-32\lib\site-packages\netmiko\ssh_dispatcher.py", line 218, in ConnectHandler
    return ConnectionClass(*args, **kwargs)
  File "C:\Users\m_buck\AppData\Local\Programs\Python\Python37-32\lib\site-packages\netmiko\base_connection.py", line 270, in __init__
    self.establish_connection()
  File "C:\Users\m_buck\AppData\Local\Programs\Python\Python37-32\lib\site-packages\netmiko\base_connection.py", line 787, in establish_connection
    raise NetMikoTimeoutException(msg)
netmiko.ssh_exception.NetMikoTimeoutException: Connection to device timed-out: cisco_ios 10.161.43.228:22

2019-05-15 14:39:36,747 - nornir.core.task -    ERROR -      start() - NET14070-DSL-TONBRIDGE.CE1: Traceback (most recent call last):
  File "C:\Users\m_buck\AppData\Local\Programs\Python\Python37-32\lib\site-packages\netmiko\base_connection.py", line 782, in establish_connection
    self.remote_conn_pre.connect(**ssh_connect_params)
  File "C:\Users\m_buck\AppData\Local\Programs\Python\Python37-32\lib\site-packages\paramiko\client.py", line 343, in connect
    retry_on_signal(lambda: sock.connect(addr))
  File "C:\Users\m_buck\AppData\Local\Programs\Python\Python37-32\lib\site-packages\paramiko\util.py", line 280, in retry_on_signal
    return function()
  File "C:\Users\m_buck\AppData\Local\Programs\Python\Python37-32\lib\site-packages\paramiko\client.py", line 343, in <lambda>
    retry_on_signal(lambda: sock.connect(addr))
TimeoutError: [WinError 10060] A connection attempt failed because the connected party did not properly respond after a period of time, or established connection failed because connected host has failed to respond

During handling of the above exception, another exception occurred:

Traceback (most recent call last):
  File "C:\Users\m_buck\AppData\Local\Programs\Python\Python37-32\lib\site-packages\nornir\core\task.py", line 62, in start
    r = self.task(self, **self.params)
  File "C:\Users\m_buck\AppData\Local\Programs\Python\Python37-32\lib\site-packages\nornir\plugins\tasks\networking\netmiko_send_command.py", line 26, in netmiko_send_command
    net_connect = task.host.get_connection("netmiko", task.nornir.config)
  File "C:\Users\m_buck\AppData\Local\Programs\Python\Python37-32\lib\site-packages\nornir\core\inventory.py", line 297, in get_connection
    **self.get_connection_parameters(connection).dict(),
  File "C:\Users\m_buck\AppData\Local\Programs\Python\Python37-32\lib\site-packages\nornir\core\inventory.py", line 347, in open_connection
    configuration=configuration,
  File "C:\Users\m_buck\AppData\Local\Programs\Python\Python37-32\lib\site-packages\nornir\plugins\connections\netmiko.py", line 51, in open
    self.connection = ConnectHandler(**parameters)
  File "C:\Users\m_buck\AppData\Local\Programs\Python\Python37-32\lib\site-packages\netmiko\ssh_dispatcher.py", line 218, in ConnectHandler
    return ConnectionClass(*args, **kwargs)
  File "C:\Users\m_buck\AppData\Local\Programs\Python\Python37-32\lib\site-packages\netmiko\base_connection.py", line 270, in __init__
    self.establish_connection()
  File "C:\Users\m_buck\AppData\Local\Programs\Python\Python37-32\lib\site-packages\netmiko\base_connection.py", line 787, in establish_connection
    raise NetMikoTimeoutException(msg)
netmiko.ssh_exception.NetMikoTimeoutException: Connection to device timed-out: cisco_ios 10.161.43.228:22

2019-05-15 14:43:27,260 -  nornir.core -     INFO -        run() - Running task 'netmiko_send_command' with num_workers: 100
2019-05-15 14:43:27,260 -  nornir.core -     INFO -        run() - Running task 'netmiko_send_command' with num_workers: 100
2019-05-15 14:43:27,261 -  nornir.core -    DEBUG -        run() - {'command_string': 'sh int status'}
2019-05-15 14:43:27,261 -  nornir.core -    DEBUG -        run() - {'command_string': 'sh int status'}
2019-05-15 14:43:27,298 - nornir.core.task -     INFO -      start() - NET002A-101HSMANCHESTER.CE1: netmiko_send_command: running task
2019-05-15 14:43:27,298 - nornir.core.task -     INFO -      start() - NET14070-DSL-TONBRIDGE.CE1: netmiko_send_command: running task
2019-05-15 14:43:27,298 - nornir.core.task -     INFO -      start() - NET002A-101HSMANCHESTER.CE1: netmiko_send_command: running task
2019-05-15 14:43:27,298 - nornir.core.task -     INFO -      start() - NET14070-DSL-TONBRIDGE.CE1: netmiko_send_command: running task
2019-05-15 14:43:48,315 - nornir.core.task -    ERROR -      start() - NET002A-101HSMANCHESTER.CE1: Traceback (most recent call last):
  File "C:\Users\m_buck\AppData\Local\Programs\Python\Python37-32\lib\site-packages\netmiko\base_connection.py", line 782, in establish_connection
    self.remote_conn_pre.connect(**ssh_connect_params)
  File "C:\Users\m_buck\AppData\Local\Programs\Python\Python37-32\lib\site-packages\paramiko\client.py", line 343, in connect
    retry_on_signal(lambda: sock.connect(addr))
  File "C:\Users\m_buck\AppData\Local\Programs\Python\Python37-32\lib\site-packages\paramiko\util.py", line 280, in retry_on_signal
    return function()
  File "C:\Users\m_buck\AppData\Local\Programs\Python\Python37-32\lib\site-packages\paramiko\client.py", line 343, in <lambda>
    retry_on_signal(lambda: sock.connect(addr))
TimeoutError: [WinError 10060] A connection attempt failed because the connected party did not properly respond after a period of time, or established connection failed because connected host has failed to respond

During handling of the above exception, another exception occurred:

Traceback (most recent call last):
  File "C:\Users\m_buck\AppData\Local\Programs\Python\Python37-32\lib\site-packages\nornir\core\task.py", line 62, in start
    r = self.task(self, **self.params)
  File "C:\Users\m_buck\AppData\Local\Programs\Python\Python37-32\lib\site-packages\nornir\plugins\tasks\networking\netmiko_send_command.py", line 26, in netmiko_send_command
    net_connect = task.host.get_connection("netmiko", task.nornir.config)
  File "C:\Users\m_buck\AppData\Local\Programs\Python\Python37-32\lib\site-packages\nornir\core\inventory.py", line 297, in get_connection
    **self.get_connection_parameters(connection).dict(),
  File "C:\Users\m_buck\AppData\Local\Programs\Python\Python37-32\lib\site-packages\nornir\core\inventory.py", line 347, in open_connection
    configuration=configuration,
  File "C:\Users\m_buck\AppData\Local\Programs\Python\Python37-32\lib\site-packages\nornir\plugins\connections\netmiko.py", line 51, in open
    self.connection = ConnectHandler(**parameters)
  File "C:\Users\m_buck\AppData\Local\Programs\Python\Python37-32\lib\site-packages\netmiko\ssh_dispatcher.py", line 218, in ConnectHandler
    return ConnectionClass(*args, **kwargs)
  File "C:\Users\m_buck\AppData\Local\Programs\Python\Python37-32\lib\site-packages\netmiko\base_connection.py", line 270, in __init__
    self.establish_connection()
  File "C:\Users\m_buck\AppData\Local\Programs\Python\Python37-32\lib\site-packages\netmiko\base_connection.py", line 787, in establish_connection
    raise NetMikoTimeoutException(msg)
netmiko.ssh_exception.NetMikoTimeoutException: Connection to device timed-out: cisco_ios 10.161.37.212:22

2019-05-15 14:43:48,315 - nornir.core.task -    ERROR -      start() - NET002A-101HSMANCHESTER.CE1: Traceback (most recent call last):
  File "C:\Users\m_buck\AppData\Local\Programs\Python\Python37-32\lib\site-packages\netmiko\base_connection.py", line 782, in establish_connection
    self.remote_conn_pre.connect(**ssh_connect_params)
  File "C:\Users\m_buck\AppData\Local\Programs\Python\Python37-32\lib\site-packages\paramiko\client.py", line 343, in connect
    retry_on_signal(lambda: sock.connect(addr))
  File "C:\Users\m_buck\AppData\Local\Programs\Python\Python37-32\lib\site-packages\paramiko\util.py", line 280, in retry_on_signal
    return function()
  File "C:\Users\m_buck\AppData\Local\Programs\Python\Python37-32\lib\site-packages\paramiko\client.py", line 343, in <lambda>
    retry_on_signal(lambda: sock.connect(addr))
TimeoutError: [WinError 10060] A connection attempt failed because the connected party did not properly respond after a period of time, or established connection failed because connected host has failed to respond

During handling of the above exception, another exception occurred:

Traceback (most recent call last):
  File "C:\Users\m_buck\AppData\Local\Programs\Python\Python37-32\lib\site-packages\nornir\core\task.py", line 62, in start
    r = self.task(self, **self.params)
  File "C:\Users\m_buck\AppData\Local\Programs\Python\Python37-32\lib\site-packages\nornir\plugins\tasks\networking\netmiko_send_command.py", line 26, in netmiko_send_command
    net_connect = task.host.get_connection("netmiko", task.nornir.config)
  File "C:\Users\m_buck\AppData\Local\Programs\Python\Python37-32\lib\site-packages\nornir\core\inventory.py", line 297, in get_connection
    **self.get_connection_parameters(connection).dict(),
  File "C:\Users\m_buck\AppData\Local\Programs\Python\Python37-32\lib\site-packages\nornir\core\inventory.py", line 347, in open_connection
    configuration=configuration,
  File "C:\Users\m_buck\AppData\Local\Programs\Python\Python37-32\lib\site-packages\nornir\plugins\connections\netmiko.py", line 51, in open
    self.connection = ConnectHandler(**parameters)
  File "C:\Users\m_buck\AppData\Local\Programs\Python\Python37-32\lib\site-packages\netmiko\ssh_dispatcher.py", line 218, in ConnectHandler
    return ConnectionClass(*args, **kwargs)
  File "C:\Users\m_buck\AppData\Local\Programs\Python\Python37-32\lib\site-packages\netmiko\base_connection.py", line 270, in __init__
    self.establish_connection()
  File "C:\Users\m_buck\AppData\Local\Programs\Python\Python37-32\lib\site-packages\netmiko\base_connection.py", line 787, in establish_connection
    raise NetMikoTimeoutException(msg)
netmiko.ssh_exception.NetMikoTimeoutException: Connection to device timed-out: cisco_ios 10.161.37.212:22

2019-05-15 14:43:48,315 - nornir.core.task -    ERROR -      start() - NET14070-DSL-TONBRIDGE.CE1: Traceback (most recent call last):
  File "C:\Users\m_buck\AppData\Local\Programs\Python\Python37-32\lib\site-packages\netmiko\base_connection.py", line 782, in establish_connection
    self.remote_conn_pre.connect(**ssh_connect_params)
  File "C:\Users\m_buck\AppData\Local\Programs\Python\Python37-32\lib\site-packages\paramiko\client.py", line 343, in connect
    retry_on_signal(lambda: sock.connect(addr))
  File "C:\Users\m_buck\AppData\Local\Programs\Python\Python37-32\lib\site-packages\paramiko\util.py", line 280, in retry_on_signal
    return function()
  File "C:\Users\m_buck\AppData\Local\Programs\Python\Python37-32\lib\site-packages\paramiko\client.py", line 343, in <lambda>
    retry_on_signal(lambda: sock.connect(addr))
TimeoutError: [WinError 10060] A connection attempt failed because the connected party did not properly respond after a period of time, or established connection failed because connected host has failed to respond

During handling of the above exception, another exception occurred:

Traceback (most recent call last):
  File "C:\Users\m_buck\AppData\Local\Programs\Python\Python37-32\lib\site-packages\nornir\core\task.py", line 62, in start
    r = self.task(self, **self.params)
  File "C:\Users\m_buck\AppData\Local\Programs\Python\Python37-32\lib\site-packages\nornir\plugins\tasks\networking\netmiko_send_command.py", line 26, in netmiko_send_command
    net_connect = task.host.get_connection("netmiko", task.nornir.config)
  File "C:\Users\m_buck\AppData\Local\Programs\Python\Python37-32\lib\site-packages\nornir\core\inventory.py", line 297, in get_connection
    **self.get_connection_parameters(connection).dict(),
  File "C:\Users\m_buck\AppData\Local\Programs\Python\Python37-32\lib\site-packages\nornir\core\inventory.py", line 347, in open_connection
    configuration=configuration,
  File "C:\Users\m_buck\AppData\Local\Programs\Python\Python37-32\lib\site-packages\nornir\plugins\connections\netmiko.py", line 51, in open
    self.connection = ConnectHandler(**parameters)
  File "C:\Users\m_buck\AppData\Local\Programs\Python\Python37-32\lib\site-packages\netmiko\ssh_dispatcher.py", line 218, in ConnectHandler
    return ConnectionClass(*args, **kwargs)
  File "C:\Users\m_buck\AppData\Local\Programs\Python\Python37-32\lib\site-packages\netmiko\base_connection.py", line 270, in __init__
    self.establish_connection()
  File "C:\Users\m_buck\AppData\Local\Programs\Python\Python37-32\lib\site-packages\netmiko\base_connection.py", line 787, in establish_connection
    raise NetMikoTimeoutException(msg)
netmiko.ssh_exception.NetMikoTimeoutException: Connection to device timed-out: cisco_ios 10.161.43.228:22

2019-05-15 14:43:48,315 - nornir.core.task -    ERROR -      start() - NET14070-DSL-TONBRIDGE.CE1: Traceback (most recent call last):
  File "C:\Users\m_buck\AppData\Local\Programs\Python\Python37-32\lib\site-packages\netmiko\base_connection.py", line 782, in establish_connection
    self.remote_conn_pre.connect(**ssh_connect_params)
  File "C:\Users\m_buck\AppData\Local\Programs\Python\Python37-32\lib\site-packages\paramiko\client.py", line 343, in connect
    retry_on_signal(lambda: sock.connect(addr))
  File "C:\Users\m_buck\AppData\Local\Programs\Python\Python37-32\lib\site-packages\paramiko\util.py", line 280, in retry_on_signal
    return function()
  File "C:\Users\m_buck\AppData\Local\Programs\Python\Python37-32\lib\site-packages\paramiko\client.py", line 343, in <lambda>
    retry_on_signal(lambda: sock.connect(addr))
TimeoutError: [WinError 10060] A connection attempt failed because the connected party did not properly respond after a period of time, or established connection failed because connected host has failed to respond

During handling of the above exception, another exception occurred:

Traceback (most recent call last):
  File "C:\Users\m_buck\AppData\Local\Programs\Python\Python37-32\lib\site-packages\nornir\core\task.py", line 62, in start
    r = self.task(self, **self.params)
  File "C:\Users\m_buck\AppData\Local\Programs\Python\Python37-32\lib\site-packages\nornir\plugins\tasks\networking\netmiko_send_command.py", line 26, in netmiko_send_command
    net_connect = task.host.get_connection("netmiko", task.nornir.config)
  File "C:\Users\m_buck\AppData\Local\Programs\Python\Python37-32\lib\site-packages\nornir\core\inventory.py", line 297, in get_connection
    **self.get_connection_parameters(connection).dict(),
  File "C:\Users\m_buck\AppData\Local\Programs\Python\Python37-32\lib\site-packages\nornir\core\inventory.py", line 347, in open_connection
    configuration=configuration,
  File "C:\Users\m_buck\AppData\Local\Programs\Python\Python37-32\lib\site-packages\nornir\plugins\connections\netmiko.py", line 51, in open
    self.connection = ConnectHandler(**parameters)
  File "C:\Users\m_buck\AppData\Local\Programs\Python\Python37-32\lib\site-packages\netmiko\ssh_dispatcher.py", line 218, in ConnectHandler
    return ConnectionClass(*args, **kwargs)
  File "C:\Users\m_buck\AppData\Local\Programs\Python\Python37-32\lib\site-packages\netmiko\base_connection.py", line 270, in __init__
    self.establish_connection()
  File "C:\Users\m_buck\AppData\Local\Programs\Python\Python37-32\lib\site-packages\netmiko\base_connection.py", line 787, in establish_connection
    raise NetMikoTimeoutException(msg)
netmiko.ssh_exception.NetMikoTimeoutException: Connection to device timed-out: cisco_ios 10.161.43.228:22

2019-05-15 14:44:14,634 -  nornir.core -     INFO -        run() - Running task 'netmiko_send_command' with num_workers: 100
2019-05-15 14:44:14,634 -  nornir.core -     INFO -        run() - Running task 'netmiko_send_command' with num_workers: 100
2019-05-15 14:44:14,635 -  nornir.core -    DEBUG -        run() - {'command_string': 'sh int status'}
2019-05-15 14:44:14,635 -  nornir.core -    DEBUG -        run() - {'command_string': 'sh int status'}
2019-05-15 14:44:14,663 - nornir.core.task -     INFO -      start() - NET002A-101HSMANCHESTER.CE1: netmiko_send_command: running task
2019-05-15 14:44:14,663 - nornir.core.task -     INFO -      start() - NET14070-DSL-TONBRIDGE.CE1: netmiko_send_command: running task
2019-05-15 14:44:14,663 - nornir.core.task -     INFO -      start() - NET002A-101HSMANCHESTER.CE1: netmiko_send_command: running task
2019-05-15 14:44:14,663 - nornir.core.task -     INFO -      start() - NET14070-DSL-TONBRIDGE.CE1: netmiko_send_command: running task
2019-05-15 14:44:35,681 - nornir.core.task -    ERROR -      start() - NET002A-101HSMANCHESTER.CE1: Traceback (most recent call last):
  File "C:\Users\m_buck\AppData\Local\Programs\Python\Python37-32\lib\site-packages\netmiko\base_connection.py", line 782, in establish_connection
    self.remote_conn_pre.connect(**ssh_connect_params)
  File "C:\Users\m_buck\AppData\Local\Programs\Python\Python37-32\lib\site-packages\paramiko\client.py", line 343, in connect
    retry_on_signal(lambda: sock.connect(addr))
  File "C:\Users\m_buck\AppData\Local\Programs\Python\Python37-32\lib\site-packages\paramiko\util.py", line 280, in retry_on_signal
    return function()
  File "C:\Users\m_buck\AppData\Local\Programs\Python\Python37-32\lib\site-packages\paramiko\client.py", line 343, in <lambda>
    retry_on_signal(lambda: sock.connect(addr))
TimeoutError: [WinError 10060] A connection attempt failed because the connected party did not properly respond after a period of time, or established connection failed because connected host has failed to respond

During handling of the above exception, another exception occurred:

Traceback (most recent call last):
  File "C:\Users\m_buck\AppData\Local\Programs\Python\Python37-32\lib\site-packages\nornir\core\task.py", line 62, in start
    r = self.task(self, **self.params)
  File "C:\Users\m_buck\AppData\Local\Programs\Python\Python37-32\lib\site-packages\nornir\plugins\tasks\networking\netmiko_send_command.py", line 26, in netmiko_send_command
    net_connect = task.host.get_connection("netmiko", task.nornir.config)
  File "C:\Users\m_buck\AppData\Local\Programs\Python\Python37-32\lib\site-packages\nornir\core\inventory.py", line 297, in get_connection
    **self.get_connection_parameters(connection).dict(),
  File "C:\Users\m_buck\AppData\Local\Programs\Python\Python37-32\lib\site-packages\nornir\core\inventory.py", line 347, in open_connection
    configuration=configuration,
  File "C:\Users\m_buck\AppData\Local\Programs\Python\Python37-32\lib\site-packages\nornir\plugins\connections\netmiko.py", line 51, in open
    self.connection = ConnectHandler(**parameters)
  File "C:\Users\m_buck\AppData\Local\Programs\Python\Python37-32\lib\site-packages\netmiko\ssh_dispatcher.py", line 218, in ConnectHandler
    return ConnectionClass(*args, **kwargs)
  File "C:\Users\m_buck\AppData\Local\Programs\Python\Python37-32\lib\site-packages\netmiko\base_connection.py", line 270, in __init__
    self.establish_connection()
  File "C:\Users\m_buck\AppData\Local\Programs\Python\Python37-32\lib\site-packages\netmiko\base_connection.py", line 787, in establish_connection
    raise NetMikoTimeoutException(msg)
netmiko.ssh_exception.NetMikoTimeoutException: Connection to device timed-out: cisco_ios 10.161.37.212:22

2019-05-15 14:44:35,681 - nornir.core.task -    ERROR -      start() - NET002A-101HSMANCHESTER.CE1: Traceback (most recent call last):
  File "C:\Users\m_buck\AppData\Local\Programs\Python\Python37-32\lib\site-packages\netmiko\base_connection.py", line 782, in establish_connection
    self.remote_conn_pre.connect(**ssh_connect_params)
  File "C:\Users\m_buck\AppData\Local\Programs\Python\Python37-32\lib\site-packages\paramiko\client.py", line 343, in connect
    retry_on_signal(lambda: sock.connect(addr))
  File "C:\Users\m_buck\AppData\Local\Programs\Python\Python37-32\lib\site-packages\paramiko\util.py", line 280, in retry_on_signal
    return function()
  File "C:\Users\m_buck\AppData\Local\Programs\Python\Python37-32\lib\site-packages\paramiko\client.py", line 343, in <lambda>
    retry_on_signal(lambda: sock.connect(addr))
TimeoutError: [WinError 10060] A connection attempt failed because the connected party did not properly respond after a period of time, or established connection failed because connected host has failed to respond

During handling of the above exception, another exception occurred:

Traceback (most recent call last):
  File "C:\Users\m_buck\AppData\Local\Programs\Python\Python37-32\lib\site-packages\nornir\core\task.py", line 62, in start
    r = self.task(self, **self.params)
  File "C:\Users\m_buck\AppData\Local\Programs\Python\Python37-32\lib\site-packages\nornir\plugins\tasks\networking\netmiko_send_command.py", line 26, in netmiko_send_command
    net_connect = task.host.get_connection("netmiko", task.nornir.config)
  File "C:\Users\m_buck\AppData\Local\Programs\Python\Python37-32\lib\site-packages\nornir\core\inventory.py", line 297, in get_connection
    **self.get_connection_parameters(connection).dict(),
  File "C:\Users\m_buck\AppData\Local\Programs\Python\Python37-32\lib\site-packages\nornir\core\inventory.py", line 347, in open_connection
    configuration=configuration,
  File "C:\Users\m_buck\AppData\Local\Programs\Python\Python37-32\lib\site-packages\nornir\plugins\connections\netmiko.py", line 51, in open
    self.connection = ConnectHandler(**parameters)
  File "C:\Users\m_buck\AppData\Local\Programs\Python\Python37-32\lib\site-packages\netmiko\ssh_dispatcher.py", line 218, in ConnectHandler
    return ConnectionClass(*args, **kwargs)
  File "C:\Users\m_buck\AppData\Local\Programs\Python\Python37-32\lib\site-packages\netmiko\base_connection.py", line 270, in __init__
    self.establish_connection()
  File "C:\Users\m_buck\AppData\Local\Programs\Python\Python37-32\lib\site-packages\netmiko\base_connection.py", line 787, in establish_connection
    raise NetMikoTimeoutException(msg)
netmiko.ssh_exception.NetMikoTimeoutException: Connection to device timed-out: cisco_ios 10.161.37.212:22

2019-05-15 14:44:35,684 - nornir.core.task -    ERROR -      start() - NET14070-DSL-TONBRIDGE.CE1: Traceback (most recent call last):
  File "C:\Users\m_buck\AppData\Local\Programs\Python\Python37-32\lib\site-packages\netmiko\base_connection.py", line 782, in establish_connection
    self.remote_conn_pre.connect(**ssh_connect_params)
  File "C:\Users\m_buck\AppData\Local\Programs\Python\Python37-32\lib\site-packages\paramiko\client.py", line 343, in connect
    retry_on_signal(lambda: sock.connect(addr))
  File "C:\Users\m_buck\AppData\Local\Programs\Python\Python37-32\lib\site-packages\paramiko\util.py", line 280, in retry_on_signal
    return function()
  File "C:\Users\m_buck\AppData\Local\Programs\Python\Python37-32\lib\site-packages\paramiko\client.py", line 343, in <lambda>
    retry_on_signal(lambda: sock.connect(addr))
TimeoutError: [WinError 10060] A connection attempt failed because the connected party did not properly respond after a period of time, or established connection failed because connected host has failed to respond

During handling of the above exception, another exception occurred:

Traceback (most recent call last):
  File "C:\Users\m_buck\AppData\Local\Programs\Python\Python37-32\lib\site-packages\nornir\core\task.py", line 62, in start
    r = self.task(self, **self.params)
  File "C:\Users\m_buck\AppData\Local\Programs\Python\Python37-32\lib\site-packages\nornir\plugins\tasks\networking\netmiko_send_command.py", line 26, in netmiko_send_command
    net_connect = task.host.get_connection("netmiko", task.nornir.config)
  File "C:\Users\m_buck\AppData\Local\Programs\Python\Python37-32\lib\site-packages\nornir\core\inventory.py", line 297, in get_connection
    **self.get_connection_parameters(connection).dict(),
  File "C:\Users\m_buck\AppData\Local\Programs\Python\Python37-32\lib\site-packages\nornir\core\inventory.py", line 347, in open_connection
    configuration=configuration,
  File "C:\Users\m_buck\AppData\Local\Programs\Python\Python37-32\lib\site-packages\nornir\plugins\connections\netmiko.py", line 51, in open
    self.connection = ConnectHandler(**parameters)
  File "C:\Users\m_buck\AppData\Local\Programs\Python\Python37-32\lib\site-packages\netmiko\ssh_dispatcher.py", line 218, in ConnectHandler
    return ConnectionClass(*args, **kwargs)
  File "C:\Users\m_buck\AppData\Local\Programs\Python\Python37-32\lib\site-packages\netmiko\base_connection.py", line 270, in __init__
    self.establish_connection()
  File "C:\Users\m_buck\AppData\Local\Programs\Python\Python37-32\lib\site-packages\netmiko\base_connection.py", line 787, in establish_connection
    raise NetMikoTimeoutException(msg)
netmiko.ssh_exception.NetMikoTimeoutException: Connection to device timed-out: cisco_ios 10.161.43.228:22

2019-05-15 14:44:35,684 - nornir.core.task -    ERROR -      start() - NET14070-DSL-TONBRIDGE.CE1: Traceback (most recent call last):
  File "C:\Users\m_buck\AppData\Local\Programs\Python\Python37-32\lib\site-packages\netmiko\base_connection.py", line 782, in establish_connection
    self.remote_conn_pre.connect(**ssh_connect_params)
  File "C:\Users\m_buck\AppData\Local\Programs\Python\Python37-32\lib\site-packages\paramiko\client.py", line 343, in connect
    retry_on_signal(lambda: sock.connect(addr))
  File "C:\Users\m_buck\AppData\Local\Programs\Python\Python37-32\lib\site-packages\paramiko\util.py", line 280, in retry_on_signal
    return function()
  File "C:\Users\m_buck\AppData\Local\Programs\Python\Python37-32\lib\site-packages\paramiko\client.py", line 343, in <lambda>
    retry_on_signal(lambda: sock.connect(addr))
TimeoutError: [WinError 10060] A connection attempt failed because the connected party did not properly respond after a period of time, or established connection failed because connected host has failed to respond

During handling of the above exception, another exception occurred:

Traceback (most recent call last):
  File "C:\Users\m_buck\AppData\Local\Programs\Python\Python37-32\lib\site-packages\nornir\core\task.py", line 62, in start
    r = self.task(self, **self.params)
  File "C:\Users\m_buck\AppData\Local\Programs\Python\Python37-32\lib\site-packages\nornir\plugins\tasks\networking\netmiko_send_command.py", line 26, in netmiko_send_command
    net_connect = task.host.get_connection("netmiko", task.nornir.config)
  File "C:\Users\m_buck\AppData\Local\Programs\Python\Python37-32\lib\site-packages\nornir\core\inventory.py", line 297, in get_connection
    **self.get_connection_parameters(connection).dict(),
  File "C:\Users\m_buck\AppData\Local\Programs\Python\Python37-32\lib\site-packages\nornir\core\inventory.py", line 347, in open_connection
    configuration=configuration,
  File "C:\Users\m_buck\AppData\Local\Programs\Python\Python37-32\lib\site-packages\nornir\plugins\connections\netmiko.py", line 51, in open
    self.connection = ConnectHandler(**parameters)
  File "C:\Users\m_buck\AppData\Local\Programs\Python\Python37-32\lib\site-packages\netmiko\ssh_dispatcher.py", line 218, in ConnectHandler
    return ConnectionClass(*args, **kwargs)
  File "C:\Users\m_buck\AppData\Local\Programs\Python\Python37-32\lib\site-packages\netmiko\base_connection.py", line 270, in __init__
    self.establish_connection()
  File "C:\Users\m_buck\AppData\Local\Programs\Python\Python37-32\lib\site-packages\netmiko\base_connection.py", line 787, in establish_connection
    raise NetMikoTimeoutException(msg)
netmiko.ssh_exception.NetMikoTimeoutException: Connection to device timed-out: cisco_ios 10.161.43.228:22

2019-05-15 14:44:53,428 -  nornir.core -     INFO -        run() - Running task 'netmiko_send_command' with num_workers: 100
2019-05-15 14:44:53,428 -  nornir.core -     INFO -        run() - Running task 'netmiko_send_command' with num_workers: 100
2019-05-15 14:44:53,429 -  nornir.core -    DEBUG -        run() - {'command_string': 'sh int status'}
2019-05-15 14:44:53,429 -  nornir.core -    DEBUG -        run() - {'command_string': 'sh int status'}
2019-05-15 14:44:53,460 - nornir.core.task -     INFO -      start() - NET14070-DSL-TONBRIDGE.CE1: netmiko_send_command: running task
2019-05-15 14:44:53,460 - nornir.core.task -     INFO -      start() - NET14070-DSL-TONBRIDGE.CE1: netmiko_send_command: running task
2019-05-15 14:45:14,468 - nornir.core.task -    ERROR -      start() - NET14070-DSL-TONBRIDGE.CE1: Traceback (most recent call last):
  File "C:\Users\m_buck\AppData\Local\Programs\Python\Python37-32\lib\site-packages\netmiko\base_connection.py", line 782, in establish_connection
    self.remote_conn_pre.connect(**ssh_connect_params)
  File "C:\Users\m_buck\AppData\Local\Programs\Python\Python37-32\lib\site-packages\paramiko\client.py", line 343, in connect
    retry_on_signal(lambda: sock.connect(addr))
  File "C:\Users\m_buck\AppData\Local\Programs\Python\Python37-32\lib\site-packages\paramiko\util.py", line 280, in retry_on_signal
    return function()
  File "C:\Users\m_buck\AppData\Local\Programs\Python\Python37-32\lib\site-packages\paramiko\client.py", line 343, in <lambda>
    retry_on_signal(lambda: sock.connect(addr))
TimeoutError: [WinError 10060] A connection attempt failed because the connected party did not properly respond after a period of time, or established connection failed because connected host has failed to respond

During handling of the above exception, another exception occurred:

Traceback (most recent call last):
  File "C:\Users\m_buck\AppData\Local\Programs\Python\Python37-32\lib\site-packages\nornir\core\task.py", line 62, in start
    r = self.task(self, **self.params)
  File "C:\Users\m_buck\AppData\Local\Programs\Python\Python37-32\lib\site-packages\nornir\plugins\tasks\networking\netmiko_send_command.py", line 26, in netmiko_send_command
    net_connect = task.host.get_connection("netmiko", task.nornir.config)
  File "C:\Users\m_buck\AppData\Local\Programs\Python\Python37-32\lib\site-packages\nornir\core\inventory.py", line 297, in get_connection
    **self.get_connection_parameters(connection).dict(),
  File "C:\Users\m_buck\AppData\Local\Programs\Python\Python37-32\lib\site-packages\nornir\core\inventory.py", line 347, in open_connection
    configuration=configuration,
  File "C:\Users\m_buck\AppData\Local\Programs\Python\Python37-32\lib\site-packages\nornir\plugins\connections\netmiko.py", line 51, in open
    self.connection = ConnectHandler(**parameters)
  File "C:\Users\m_buck\AppData\Local\Programs\Python\Python37-32\lib\site-packages\netmiko\ssh_dispatcher.py", line 218, in ConnectHandler
    return ConnectionClass(*args, **kwargs)
  File "C:\Users\m_buck\AppData\Local\Programs\Python\Python37-32\lib\site-packages\netmiko\base_connection.py", line 270, in __init__
    self.establish_connection()
  File "C:\Users\m_buck\AppData\Local\Programs\Python\Python37-32\lib\site-packages\netmiko\base_connection.py", line 787, in establish_connection
    raise NetMikoTimeoutException(msg)
netmiko.ssh_exception.NetMikoTimeoutException: Connection to device timed-out: cisco_ios 10.161.43.228:22

2019-05-15 14:45:14,468 - nornir.core.task -    ERROR -      start() - NET14070-DSL-TONBRIDGE.CE1: Traceback (most recent call last):
  File "C:\Users\m_buck\AppData\Local\Programs\Python\Python37-32\lib\site-packages\netmiko\base_connection.py", line 782, in establish_connection
    self.remote_conn_pre.connect(**ssh_connect_params)
  File "C:\Users\m_buck\AppData\Local\Programs\Python\Python37-32\lib\site-packages\paramiko\client.py", line 343, in connect
    retry_on_signal(lambda: sock.connect(addr))
  File "C:\Users\m_buck\AppData\Local\Programs\Python\Python37-32\lib\site-packages\paramiko\util.py", line 280, in retry_on_signal
    return function()
  File "C:\Users\m_buck\AppData\Local\Programs\Python\Python37-32\lib\site-packages\paramiko\client.py", line 343, in <lambda>
    retry_on_signal(lambda: sock.connect(addr))
TimeoutError: [WinError 10060] A connection attempt failed because the connected party did not properly respond after a period of time, or established connection failed because connected host has failed to respond

During handling of the above exception, another exception occurred:

Traceback (most recent call last):
  File "C:\Users\m_buck\AppData\Local\Programs\Python\Python37-32\lib\site-packages\nornir\core\task.py", line 62, in start
    r = self.task(self, **self.params)
  File "C:\Users\m_buck\AppData\Local\Programs\Python\Python37-32\lib\site-packages\nornir\plugins\tasks\networking\netmiko_send_command.py", line 26, in netmiko_send_command
    net_connect = task.host.get_connection("netmiko", task.nornir.config)
  File "C:\Users\m_buck\AppData\Local\Programs\Python\Python37-32\lib\site-packages\nornir\core\inventory.py", line 297, in get_connection
    **self.get_connection_parameters(connection).dict(),
  File "C:\Users\m_buck\AppData\Local\Programs\Python\Python37-32\lib\site-packages\nornir\core\inventory.py", line 347, in open_connection
    configuration=configuration,
  File "C:\Users\m_buck\AppData\Local\Programs\Python\Python37-32\lib\site-packages\nornir\plugins\connections\netmiko.py", line 51, in open
    self.connection = ConnectHandler(**parameters)
  File "C:\Users\m_buck\AppData\Local\Programs\Python\Python37-32\lib\site-packages\netmiko\ssh_dispatcher.py", line 218, in ConnectHandler
    return ConnectionClass(*args, **kwargs)
  File "C:\Users\m_buck\AppData\Local\Programs\Python\Python37-32\lib\site-packages\netmiko\base_connection.py", line 270, in __init__
    self.establish_connection()
  File "C:\Users\m_buck\AppData\Local\Programs\Python\Python37-32\lib\site-packages\netmiko\base_connection.py", line 787, in establish_connection
    raise NetMikoTimeoutException(msg)
netmiko.ssh_exception.NetMikoTimeoutException: Connection to device timed-out: cisco_ios 10.161.43.228:22

2019-05-15 14:45:22,081 -  nornir.core -     INFO -        run() - Running task 'netmiko_send_command' with num_workers: 100
2019-05-15 14:45:22,081 -  nornir.core -     INFO -        run() - Running task 'netmiko_send_command' with num_workers: 100
2019-05-15 14:45:22,082 -  nornir.core -    DEBUG -        run() - {'command_string': 'sh int status'}
2019-05-15 14:45:22,082 -  nornir.core -    DEBUG -        run() - {'command_string': 'sh int status'}
2019-05-15 14:45:22,116 - nornir.core.task -     INFO -      start() - NET14070-DSL-TONBRIDGE.CE1: netmiko_send_command: running task
2019-05-15 14:45:22,116 - nornir.core.task -     INFO -      start() - NET14070-DSL-TONBRIDGE.CE1: netmiko_send_command: running task
2019-05-15 14:45:43,131 - nornir.core.task -    ERROR -      start() - NET14070-DSL-TONBRIDGE.CE1: Traceback (most recent call last):
  File "C:\Users\m_buck\AppData\Local\Programs\Python\Python37-32\lib\site-packages\netmiko\base_connection.py", line 782, in establish_connection
    self.remote_conn_pre.connect(**ssh_connect_params)
  File "C:\Users\m_buck\AppData\Local\Programs\Python\Python37-32\lib\site-packages\paramiko\client.py", line 343, in connect
    retry_on_signal(lambda: sock.connect(addr))
  File "C:\Users\m_buck\AppData\Local\Programs\Python\Python37-32\lib\site-packages\paramiko\util.py", line 280, in retry_on_signal
    return function()
  File "C:\Users\m_buck\AppData\Local\Programs\Python\Python37-32\lib\site-packages\paramiko\client.py", line 343, in <lambda>
    retry_on_signal(lambda: sock.connect(addr))
TimeoutError: [WinError 10060] A connection attempt failed because the connected party did not properly respond after a period of time, or established connection failed because connected host has failed to respond

During handling of the above exception, another exception occurred:

Traceback (most recent call last):
  File "C:\Users\m_buck\AppData\Local\Programs\Python\Python37-32\lib\site-packages\nornir\core\task.py", line 62, in start
    r = self.task(self, **self.params)
  File "C:\Users\m_buck\AppData\Local\Programs\Python\Python37-32\lib\site-packages\nornir\plugins\tasks\networking\netmiko_send_command.py", line 26, in netmiko_send_command
    net_connect = task.host.get_connection("netmiko", task.nornir.config)
  File "C:\Users\m_buck\AppData\Local\Programs\Python\Python37-32\lib\site-packages\nornir\core\inventory.py", line 297, in get_connection
    **self.get_connection_parameters(connection).dict(),
  File "C:\Users\m_buck\AppData\Local\Programs\Python\Python37-32\lib\site-packages\nornir\core\inventory.py", line 347, in open_connection
    configuration=configuration,
  File "C:\Users\m_buck\AppData\Local\Programs\Python\Python37-32\lib\site-packages\nornir\plugins\connections\netmiko.py", line 51, in open
    self.connection = ConnectHandler(**parameters)
  File "C:\Users\m_buck\AppData\Local\Programs\Python\Python37-32\lib\site-packages\netmiko\ssh_dispatcher.py", line 218, in ConnectHandler
    return ConnectionClass(*args, **kwargs)
  File "C:\Users\m_buck\AppData\Local\Programs\Python\Python37-32\lib\site-packages\netmiko\base_connection.py", line 270, in __init__
    self.establish_connection()
  File "C:\Users\m_buck\AppData\Local\Programs\Python\Python37-32\lib\site-packages\netmiko\base_connection.py", line 787, in establish_connection
    raise NetMikoTimeoutException(msg)
netmiko.ssh_exception.NetMikoTimeoutException: Connection to device timed-out: cisco_ios 10.161.43.228:22

2019-05-15 14:45:43,131 - nornir.core.task -    ERROR -      start() - NET14070-DSL-TONBRIDGE.CE1: Traceback (most recent call last):
  File "C:\Users\m_buck\AppData\Local\Programs\Python\Python37-32\lib\site-packages\netmiko\base_connection.py", line 782, in establish_connection
    self.remote_conn_pre.connect(**ssh_connect_params)
  File "C:\Users\m_buck\AppData\Local\Programs\Python\Python37-32\lib\site-packages\paramiko\client.py", line 343, in connect
    retry_on_signal(lambda: sock.connect(addr))
  File "C:\Users\m_buck\AppData\Local\Programs\Python\Python37-32\lib\site-packages\paramiko\util.py", line 280, in retry_on_signal
    return function()
  File "C:\Users\m_buck\AppData\Local\Programs\Python\Python37-32\lib\site-packages\paramiko\client.py", line 343, in <lambda>
    retry_on_signal(lambda: sock.connect(addr))
TimeoutError: [WinError 10060] A connection attempt failed because the connected party did not properly respond after a period of time, or established connection failed because connected host has failed to respond

During handling of the above exception, another exception occurred:

Traceback (most recent call last):
  File "C:\Users\m_buck\AppData\Local\Programs\Python\Python37-32\lib\site-packages\nornir\core\task.py", line 62, in start
    r = self.task(self, **self.params)
  File "C:\Users\m_buck\AppData\Local\Programs\Python\Python37-32\lib\site-packages\nornir\plugins\tasks\networking\netmiko_send_command.py", line 26, in netmiko_send_command
    net_connect = task.host.get_connection("netmiko", task.nornir.config)
  File "C:\Users\m_buck\AppData\Local\Programs\Python\Python37-32\lib\site-packages\nornir\core\inventory.py", line 297, in get_connection
    **self.get_connection_parameters(connection).dict(),
  File "C:\Users\m_buck\AppData\Local\Programs\Python\Python37-32\lib\site-packages\nornir\core\inventory.py", line 347, in open_connection
    configuration=configuration,
  File "C:\Users\m_buck\AppData\Local\Programs\Python\Python37-32\lib\site-packages\nornir\plugins\connections\netmiko.py", line 51, in open
    self.connection = ConnectHandler(**parameters)
  File "C:\Users\m_buck\AppData\Local\Programs\Python\Python37-32\lib\site-packages\netmiko\ssh_dispatcher.py", line 218, in ConnectHandler
    return ConnectionClass(*args, **kwargs)
  File "C:\Users\m_buck\AppData\Local\Programs\Python\Python37-32\lib\site-packages\netmiko\base_connection.py", line 270, in __init__
    self.establish_connection()
  File "C:\Users\m_buck\AppData\Local\Programs\Python\Python37-32\lib\site-packages\netmiko\base_connection.py", line 787, in establish_connection
    raise NetMikoTimeoutException(msg)
netmiko.ssh_exception.NetMikoTimeoutException: Connection to device timed-out: cisco_ios 10.161.43.228:22

2019-05-15 14:46:59,047 -  nornir.core -     INFO -        run() - Running task 'netmiko_send_command' with num_workers: 100
2019-05-15 14:46:59,047 -  nornir.core -     INFO -        run() - Running task 'netmiko_send_command' with num_workers: 100
2019-05-15 14:46:59,047 -  nornir.core -    DEBUG -        run() - {'command_string': 'sh int status'}
2019-05-15 14:46:59,047 -  nornir.core -    DEBUG -        run() - {'command_string': 'sh int status'}
2019-05-15 14:46:59,080 - nornir.core.task -     INFO -      start() - NET14070-DSL-TONBRIDGE.CE1: netmiko_send_command: running task
2019-05-15 14:46:59,080 - nornir.core.task -     INFO -      start() - NET14070-DSL-TONBRIDGE.CE1: netmiko_send_command: running task
2019-05-15 14:48:26,879 -  nornir.core -     INFO -        run() - Running task 'netmiko_send_command' with num_workers: 100
2019-05-15 14:48:26,879 -  nornir.core -     INFO -        run() - Running task 'netmiko_send_command' with num_workers: 100
2019-05-15 14:48:26,879 -  nornir.core -    DEBUG -        run() - {'command_string': 'sh int status'}
2019-05-15 14:48:26,879 -  nornir.core -    DEBUG -        run() - {'command_string': 'sh int status'}
2019-05-15 14:48:26,917 - nornir.core.task -     INFO -      start() - NET14070-DSL-TONBRIDGE.CE1: netmiko_send_command: running task
2019-05-15 14:48:26,917 - nornir.core.task -     INFO -      start() - NET14070-DSL-TONBRIDGE.CE1: netmiko_send_command: running task
2019-05-15 15:00:59,423 -  nornir.core -     INFO -        run() - Running task 'netmiko_send_command' with num_workers: 100
2019-05-15 15:00:59,423 -  nornir.core -     INFO -        run() - Running task 'netmiko_send_command' with num_workers: 100
2019-05-15 15:00:59,423 -  nornir.core -    DEBUG -        run() - {'command_string': 'sh int status'}
2019-05-15 15:00:59,423 -  nornir.core -    DEBUG -        run() - {'command_string': 'sh int status'}
2019-05-15 15:00:59,458 - nornir.core.task -     INFO -      start() - NET14070-DSL-TONBRIDGE.CE1: netmiko_send_command: running task
2019-05-15 15:00:59,458 - nornir.core.task -     INFO -      start() - NET14070-DSL-TONBRIDGE.CE1: netmiko_send_command: running task
2019-05-15 15:21:56,134 -  nornir.core -     INFO -        run() - Running task 'netmiko_send_command' with num_workers: 100
2019-05-15 15:21:56,134 -  nornir.core -     INFO -        run() - Running task 'netmiko_send_command' with num_workers: 100
2019-05-15 15:21:56,135 -  nornir.core -    DEBUG -        run() - {'command_string': 'sh int status'}
2019-05-15 15:21:56,135 -  nornir.core -    DEBUG -        run() - {'command_string': 'sh int status'}
2019-05-15 15:21:56,177 - nornir.core.task -     INFO -      start() - NET14070-DSL-TONBRIDGE.CE1: netmiko_send_command: running task
2019-05-15 15:21:56,177 - nornir.core.task -     INFO -      start() - NET14070-DSL-TONBRIDGE.CE1: netmiko_send_command: running task
2019-05-22 11:57:40,000 -  nornir.core -     INFO -        run() - Running task 'netmiko_send_command' with num_workers: 100
2019-05-22 11:57:40,000 -  nornir.core -     INFO -        run() - Running task 'netmiko_send_command' with num_workers: 100
2019-05-22 11:57:40,001 -  nornir.core -    DEBUG -        run() - {'command_string': 'sh int status'}
2019-05-22 11:57:40,001 -  nornir.core -    DEBUG -        run() - {'command_string': 'sh int status'}
2019-05-22 11:57:40,054 - nornir.core.task -     INFO -      start() - NET14070-DSL-TONBRIDGE.CE1: netmiko_send_command: running task
2019-05-22 11:57:40,054 - nornir.core.task -     INFO -      start() - NET14070-DSL-TONBRIDGE.CE1: netmiko_send_command: running task
